Workbook

Sheet Übersicht
B2: Zuordnung der Excel Seiten zum Kapitel 5
B4: Kapitel der Arbeit | D4: Excel Seite | E4: Inhalt
B5: 6.1 Torbetrieb und Antriebspotenzial in der Heizperiode | D5: 6.1 Torbetrieb'!A1 | E5: Analyse des Torbetriebs
B6: 6.2 Luftwechsel über die Heizperiode | D6: 6.2 Luftwechsel'!A1 | E6: Auswertung des Luftwechsels der Simulationen
B7: 6.3 Heizwärmebedarf über die Heizperiode | D7: 6.3 Heizwärmebedarf'!A1 | E7: Auswertung des Heizwärmebedarfs der Simulationen
B8: 6.4 Lastgänge
C9: 6.4.1 Dauerlinie und Lastgradienten | D9: 6.4.1 Dauerlinie'!A1 | E9: Auswertung als Dauerlinie und Lastgradienten
C10: 6.4.2 Spitzenlast nach Höhe und Zeitpunkt | D10: 6.4.2 Spitzenlasten'!A1 | E10: Auswertung der Spitzenlasten
C11: 6.4.3 Formdistanz und mehrdimensionale Skalierung | D11: 6.4.3 Formdistanz'!A1 | E11: Auswertung der Formdistanz der Lastgänge
D13: Heizlasten!A1 | E13: Heizlasten aus der Simulation (Grundlage für Kapitel 6.3 und 6.4)
D14: Lastgradienten!A1 | E14: Lastgradienten (ausgewertet aus Haizlasten, Grundlage für 6.4.1)

Sheet 6.1 Torbetrieb
B2: Zeitanteile der Torverteilung über die Heizperiode (Oktober bis April, 5088 h)
C3: Öffnungsstunden | E3: mittl. Öffnungs- fläche [m²] | F3: Fläche * Zeit | J3: Öffnungstunden | K3: Heizperiode gesamt
C4: [h] | D4: Anteil | F4: [m²h] | G4: Anteil | J4: (2.320,7 h) | K4: (5.088,0 h) | L4: Abweichung
B5: alle Tore zu | C5: 2767.3 | D5: =C5/5088 -> 0.54388758 | E5: 0 | F5: =C5*E5 -> 0 | G5: =F5/F$11 -> 0 | I5: mittlere Windgeschwindikeit [m/s] | J5: 3.449 | K5: 3.409 | L5: =J5/K5-1 -> 0.011733646
B6: nur angedockt | C6: 1831.1 | D6: =C6/5088 -> 0.35988601 | E6: 0.687 | F6: 1258.7 | G6: =F6/F$11 -> 0.20316687 | I6: mittlere Temperaturdifferenz [K] | J6: 14.103 | K6: 14.235 | L6: =J6/K6-1 -> -0.0092729189
B7: ein Tor offen | C7: 454.7 | D7: =C7/5088 -> 0.089367138 | E7: 9.417 | F7: 4284.3 | G7: =F7/F$11 -> 0.6915292 | I7: mittleres Antriebspotenzial v² ∙ ΔT [m²∙K/s²] | J7: 237 | K7: 237.33 | L7: =J7/K7-1 -> -0.001390469
B8: 2 Tore offen, eine Fassade | C8: 22.9 | D8: =C8/5088 -> 0.0045007862 | E8: 18.323 | F8: 419 | G8: =F8/F$11 -> 0.067630823 | I8: mittlere Kontrollgröße v ∙ ΔT [m∙K/s] | J8: 42.71 | K8: 43.38 | L8: =J8/K8-1 -> -0.015444905
B9: 2 Tore offen, beide Fassaden | C9: 10.6 | D9: =C9/5088 -> 0.0020833333 | E9: 18.41 | F9: 194.2 | G9: =F9/F$11 -> 0.031345837 | I9: Witterung während der Toröffnungsstunden im Vergleich zur gesamten Heizperiode. Alle Werte sind Mittelwerte über die Zeitschritte der jeweiligen Menge; das Antriebspotenzial wird je Zeitschritt gebildet und erst danach gemittelt. Die Zeilen 3 und 4 lassen sich deshalb nicht aus den Zeilen 1 und 2 berechnen — Mittel(v²·ΔT) ≠ Mittel(v)²·Mittel(ΔT). Die Abweichung bezieht sich auf den Gesamtzeitraum und ist aus ungerundeten Werten gebildet.
B10: 3 und mehr Tore offen | C10: 1.4 | D10: =C10/5088 -> 0.00027515723 | E10: 27.351 | F10: 39.2 | G10: =F10/F$11 -> 0.0063272751
B11: Summe | C11: =SUM(C5:C10) -> 5088 | D11: =SUM(D5:D10) -> 1 | F11: =SUM(F5:F10) -> 6195.4 | G11: =SUM(G5:G10) -> 1
E14: Zeitanteile gleichzeitig aktiver Tore
E15: aktive Tore | F15: Stunden [h] | G15: Zeitanteil
E16: 0 | F16: 2767.3 | G16: =F16/5088 -> 0.54388758
E17: 1 | F17: 1202.6 | G17: =F17/5088 -> 0.23636006
E18: 2 | F18: 715 | G18: =F18/5088 -> 0.14052673
E19: 3 | F19: 350 | G19: =F19/5088 -> 0.068789308
E20: 4 | F20: 43.4 | G20: =F20/5088 -> 0.0085298742
E21: 5 | F21: 7.7 | G21: =F21/5088 -> 0.0015133648
E22: 6 | F22: 2 | G22: =F22/5088 -> 0.00039308176

Sheet 6.2 Luftwechsel
K1: ACH
B2: Kumulierter Luftaustausch je Modellvariante | K2: S/N | R2: Spannen
B3: Modell | C3: ACH S/N [1/h] | D3: ACH O/W [1/h] | E3: V_aus S/N [1.000m³] | F3: V_aus O/W [1.000m³] | G3: Verhältnis O/W ÷ S/N | K3: Zustand | L3: Zeitanteil | M3: AFN_E+ | N3: DFR_BLAST | O3: DFR_DEFAULT | P3: DFR_DOE-2 | Q3: WSOA | R3: Median ACH | S3: Spanne
B4: AFN_E+ | C4: 0.12974 | D4: 0.13519 | E4: 7129.5 | F4: 7428.6 | G4: =F4/E4 -> 1.0419525 | K4: alle Tore zu | L4: 0.54388758 | M4: 0.0248 | N4: 0.025 | O4: 0.025 | P4: 0.025 | Q4: 0.025 | R4: =MEDIAN(M4:Q4) -> 0.025 | S4: =MAX(M4:Q4)-MIN(M4:Q4) -> 0.0002
B5: DFR_BLAST | C5: 0.18228 | D5: 0.19044 | E5: 10016.2 | F5: 10465 | G5: =F5/E5 -> 1.0448074 | K5: nur angedockt | L5: 0.35988601 | M5: 0.0903 | N5: 0.1139 | O5: 0.0842 | P5: 0.0674 | Q5: 0.1093 | R5: =MEDIAN(M5:Q5) -> 0.0903 | S5: =MAX(M5:Q5)-MIN(M5:Q5) -> 0.0465
B6: DFR_DEFAULT | C6: 0.12975 | D6: 0.13519 | E6: 7129.6 | F6: 7428.7 | G6: =F6/E6 -> 1.0419519 | K6: ein Tor offen | L6: 0.089367138 | M6: 0.7878 | N6: 1.2446 | O6: 0.8354 | P6: 0.6124 | Q6: 1.1949 | R6: =MEDIAN(M6:Q6) -> 0.8354 | S6: =MAX(M6:Q6)-MIN(M6:Q6) -> 0.6322
B7: DFR_DOE-2 | C7: 0.10032 | D7: 0.10424 | E7: 5512.7 | F7: 5727.8 | G7: =F7/E7 -> 1.039019 | K7: 2 Tore offen, eine Fassade | L7: 0.0045007862 | M7: 1.5231 | N7: 2.3634 | O7: 1.6067 | P7: 1.0008 | Q7: 1.9154 | R7: =MEDIAN(M7:Q7) -> 1.6067 | S7: =MAX(M7:Q7)-MIN(M7:Q7) -> 1.3626
B8: WSOA | C8: 0.174 | D8: 0.29281 | E8: 9561.6 | F8: 16089.8 | G8: =F8/E8 -> 1.6827518 | K8: 2 Tore offen, beide Fassaden | L8: 0.0020833333 | M8: 2.682 | N8: 2.3569 | O8: 1.5993 | P8: 1.2711 | Q8: 2.2406 | R8: =MEDIAN(M8:Q8) -> 2.2406 | S8: =MAX(M8:Q8)-MIN(M8:Q8) -> 1.4109
K9: 3 und mehr Tore offen | L9: 0.00027515723 | M9: 3.3469 | N9: 3.3832 | O9: 2.3425 | P9: 2.1334 | Q9: 3.6006 | R9: =MEDIAN(M9:Q9) -> 3.3469 | S9: =MAX(M9:Q9)-MIN(M9:Q9) -> 1.4672
B10: Spannen
C11: Mittel ACH_DFR [1/h] | D11: Spanne_DFR [1/h] | E11: Band_DFR min [1/h] | F11: Band_DFR max [1/h] | G11: Spanne_zw [1/h] | H11: Band_zw min [1/h] | I11: Band_zw max [1/h] | K11: O/W
B12: Tore S/N | C12: =AVERAGE(C4:C8) -> 0.143218 | D12: =MAX(C5:C7)-MIN(C5:C7) -> 0.08196 | E12: =MIN(C5:C7) -> 0.10032 | F12: =MAX(C5:C7) -> 0.18228 | G12: =MAX(C4,C8,C12)-MIN(C4,C8,C12) -> 0.04426 | H12: =MIN((C4,C8,C12)) -> 0.12974 | I12: =MAX(C4,C8,C12) -> 0.174 | K12: Zustand | L12: Zeitanteil | M12: AFN_E+ | N12: DFR_BLAST | O12: DFR_DEFAULT | P12: DFR_DOE-2 | Q12: WSOA | R12: Median ACH | S12: Spanne
B13: Tore O/W | C13: =AVERAGE(D4:D8) -> 0.171574 | D13: =MAX(D5:D7)-MIN(D5:D7) -> 0.0862 | E13: =MIN(D5:D7) -> 0.10424 | F13: =MAX(D5:D7) -> 0.19044 | G13: =MAX(D4,D8,C13)-MIN(D4,D8,C13) -> 0.15762 | H13: =MIN(D4,D8,C13) -> 0.13519 | I13: =MAX(D4,D8,C13) -> 0.29281 | K13: alle Tore zu | L13: 0.54388758 | M13: 0.0246 | N13: 0.025 | O13: 0.025 | P13: 0.025 | Q13: 0.025 | R13: =MEDIAN(M13:Q13) -> 0.025 | S13: =MAX(M13:Q13)-MIN(M13:Q13) -> 0.0004
K14: nur angedockt | L14: 0.35988601 | M14: 0.0974 | N14: 0.1185 | O14: 0.0872 | P14: 0.0696 | Q14: 0.1755 | R14: =MEDIAN(M14:Q14) -> 0.0974 | S14: =MAX(M14:Q14)-MIN(M14:Q14) -> 0.1059
K15: ein Tor offen | L15: 0.089367138 | M15: 0.7977 | N15: 1.308 | O15: 0.8775 | P15: 0.6429 | Q15: 2.1136 | R15: =MEDIAN(M15:Q15) -> 0.8775 | S15: =MAX(M15:Q15)-MIN(M15:Q15) -> 1.4707
B16: Vergleich der DFR-Innen-Spannen | K16: 2 Tore offen, eine Fassade | L16: 0.0045007862 | M16: 1.5271 | N16: 2.4848 | O16: 1.6889 | P16: 1.0516 | Q16: 3.3255 | R16: =MEDIAN(M16:Q16) -> 1.6889 | S16: =MAX(M16:Q16)-MIN(M16:Q16) -> 2.2739
B17: Fall | C17: DFR_BLAST | D17: DFR_DEFAULT | E17: DFR_DOE- | F17: Spanne_DFR | G17: max/min | K17: 2 Tore offen, beide Fassaden | L17: 0.0020833333 | M17: 3.543 | N17: 2.478 | O17: 1.6812 | P17: 1.3359 | Q17: 4.6147 | R17: =MEDIAN(M17:Q17) -> 2.478 | S17: =MAX(M17:Q17)-MIN(M17:Q17) -> 3.2788
C18: [1/h] | D18: [1/h] | E18: [1/h] | F18: [1/h] | K18: 3 und mehr Tore offen | L18: 0.00027515723 | M18: 4.5502 | N18: 3.5571 | O18: 2.4629 | P18: 2.2431 | Q18: 9.2512 | R18: =MEDIAN(M18:Q18) -> 3.5571 | S18: =MAX(M18:Q18)-MIN(M18:Q18) -> 7.0081
B19: Kap. 5 Var. 1 | C19: 3.0709 | D19: 2.553 | E19: 2.9 | F19: =MAX(C19:E19)-MIN(C19:E19) -> 0.5179 | G19: =MAX(C19:E19)/MIN(C19:E19) -> 1.2028594
B20: Kap. 5 Var. 4 | C20: 7.4139 | D20: 6.16296 | E20: 7.002 | F20: =MAX(C20:E20)-MIN(C20:E20) -> 1.25094 | G20: =MAX(C20:E20)/MIN(C20:E20) -> 1.2029771
B21: Kap. 6 S/N | C21: =C5 -> 0.18228 | D21: =C6 -> 0.12975 | E21: =C7 -> 0.10032 | F21: =MAX(C21:E21)-MIN(C21:E21) -> 0.08196 | G21: =MAX(C21:E21)/MIN(C21:E21) -> 1.8169856
B22: Kap. 6 O/W | C22: =D5 -> 0.19044 | D22: =D6 -> 0.13519 | E22: =D7 -> 0.10424 | F22: =MAX(C22:E22)-MIN(C22:E22) -> 0.0862 | G22: =MAX(C22:E22)/MIN(C22:E22) -> 1.8269378

Sheet 6.3 Heizwärmebedarf
B2: Kumulierter Heizenergiebedarf je Modellvariante | M2: S/N
B3: Modell | C3: S/N | E3: O/W | G3: Verhältnis O/W ÷ S/N | M3: Zustand | N3: Zeitanteil | O3: mittlere Heizleistung | Anteil am Jahresbedarf
C4: [MWh] | D4: [kWh/m²] | E4: [MWh] | F4: [kWh/m²] | O4: AFN_E+ | Q4: DFR_BLAST | S4: DFR_DEFAULT | U4: DFR_DOE-2 | W4: WSOA
B5: AFN_E+ | C5: 80.467 | D5: =C5/0.9 -> 89.407778 | E5: 81.356 | F5: =E5/0.9 -> 90.395556 | G5: =E5/C5 -> 1.011048 | M5: alle Tore zu | N5: 0.54388758 | O5: 11.01 | P5: 0.379 | Q5: 10.97 | R5: 0.332 | S5: 10.97 | T5: 0.394 | U5: 10.96 | V5: 0.45 | W5: 10.96 | X5: 0.354
B6: DFR_BLAST | C6: 91.35 | D6: =C6/0.9 -> 101.5 | E6: 93.709 | F6: =E6/0.9 -> 104.12111 | G6: =E6/C6 -> 1.0258238 | M6: nur angedockt | N6: 0.35988601 | O6: 12.52 | P6: 0.285 | Q6: 13.53 | R6: 0.271 | S6: 11.95 | T6: 0.284 | U6: 10.86 | V6: 0.295 | W6: 12.9 | X6: 0.276
B7: DFR_DEFAULT | C7: 77.077 | D7: =C7/0.9 -> 85.641111 | E7: 78.691 | F7: =E7/0.9 -> 87.434444 | G7: =E7/C7 -> 1.0209401 | M7: ein Tor offen | N7: 0.089367138 | O7: 51.39 | P7: 0.29 | Q7: 69.88 | R7: 0.348 | S7: 48.06 | T7: 0.284 | U7: 33.73 | V7: 0.228 | W7: 62.27 | X7: 0.33
B8: DFR_DOE-2 | C8: 67.407 | D8: =C8/0.9 -> 74.896667 | E8: 68.516 | F8: =E8/0.9 -> 76.128889 | G8: =E8/C8 -> 1.0164523 | M8: 2 Tore offen, eine Fassade | N8: 0.0045007862 | O8: 100.55 | P8: 0.029 | Q8: 136.03 | R8: 0.034 | S8: 92.59 | T8: 0.027 | U8: 53.77 | V8: 0.018 | W8: 99.99 | X8: 0.027
B9: WSOA | C9: 85.709 | D9: =C9/0.9 -> 95.232222 | E9: 109.099 | F9: =E9/0.9 -> 121.22111 | G9: =E9/C9 -> 1.2729002 | M9: 2 Tore offen, beide Fassaden | N9: 0.0020833333 | O9: 117.27 | P9: 0.015 | Q9: 109.24 | R9: 0.013 | S9: 71.65 | T9: 0.01 | U9: 51.6 | V9: 0.008 | W9: 94.22 | X9: 0.012
M10: 3 und mehr Tore offen | N10: 0.00027515723 | O10: 112.54 | P10: 0.002 | Q10: 119.12 | R10: 0.002 | S10: 76.24 | T10: 0.001 | U10: 59.69 | V10: 0.001 | W10: 115.89 | X10: 0.002
B11: Spannen in MWh
B12: Orientierung | C12: DFR | G12: Zwischen | M12: O/W
C13: Mittel Q_H,DFR | D13: S | E13: Band min | F13: Band max | G13: S | H13: Band min | I13: Band max | N13: Zeitanteil | O13: mittlere Heizleistung | Anteil am Jahresbedarf
B14: Tore S/N | C14: =AVERAGE(C6:C8) -> 78.611333 | D14: =MAX(C6:C8)-MIN(C6:C8) -> 23.943 | E14: =MIN(C6:C8) -> 67.407 | F14: =MAX(C6:C8) -> 91.35 | G14: =MAX(AVERAGE(C6:C8),C5,C9)-MIN(AVERAGE(C6:C8),C5,C9) -> 7.0976667 | H14: =MIN(AVERAGE(C6:C8),C5,C9) -> 78.611333 | I14: =MAX(AVERAGE(C6:C8),C5,C9) -> 85.709 | M14: Zustand | O14: AFN_E+ | Q14: DFR_BLAST | S14: DFR_DEFAULT | U14: DFR_DOE-2 | W14: WSOA
B15: Tore O/W | C15: =AVERAGE(E6:E8) -> 80.305333 | D15: =MAX(E6:E8)-MIN(E6:E8) -> 25.193 | E15: =MIN(E6:E8) -> 68.516 | F15: =MAX(E6:E8) -> 93.709 | G15: =MAX(AVERAGE(E6:E8),E5,E9)-MIN(AVERAGE(E6:E8),E5,E9) -> 28.793667 | H15: =MIN(AVERAGE(E6:E8),E5,E9) -> 80.305333 | I15: =MAX(AVERAGE(E6:E8),E5,E9) -> 109.099 | M15: alle Tore zu | N15: 0.54388758 | O15: 10.99 | P15: 0.374 | Q15: 11.03 | R15: 0.326 | S15: 11.02 | T15: 0.388 | U15: 11.01 | V15: 0.445 | W15: 11.02 | X15: 0.279
M16: nur angedockt | N16: 0.35988601 | O16: 12.76 | P16: 0.287 | Q16: 13.81 | R16: 0.27 | S16: 12.15 | T16: 0.283 | U16: 11.01 | V16: 0.294 | W16: 15.45 | X16: 0.259
M17: ein Tor offen | N17: 0.089367138 | O17: 51.73 | P17: 0.289 | Q17: 73.15 | R17: 0.355 | S17: 50.18 | T17: 0.29 | U17: 35.09 | V17: 0.233 | W17: 98.04 | X17: 0.409
M18: 2 Tore offen, eine Fassade | N18: 0.0045007862 | O18: 100.66 | P18: 0.028 | Q18: 142.65 | R18: 0.035 | S18: 96.98 | T18: 0.028 | U18: 56.13 | V18: 0.019 | W18: 153.15 | X18: 0.032
M19: 2 Tore offen, beide Fassaden | N19: 0.0020833333 | O19: 148.44 | P19: 0.019 | Q19: 114.8 | R19: 0.013 | S19: 75.28 | T19: 0.01 | U19: 54.2 | V19: 0.008 | W19: 177.12 | X19: 0.017
M20: 3 und mehr Tore offen | N20: 0.00027515723 | O20: 138.06 | P20: 0.002 | Q20: 125.35 | R20: 0.002 | S20: 80.05 | T20: 0.001 | U20: 62.62 | V20: 0.001 | W20: 259.93 | X20: 0.003
M22: Mehrbedarf gegenüber alle Tore zu | N22: AFN_E+ | P22: DFR_BLAST | R22: DFR_DEFAULT | T22: DFR_DOE-2 | V22: WSOA
N23: S/N | O23: O/W | P23: S/N | Q23: O/W | R23: S/N | S23: O/W | T23: S/N | U23: O/W | V23: S/N | W23: O/W
M24: nur angedockt | N24: =O6-O$5 -> 1.51 | O24: =O16-O$15 -> 1.77 | P24: =Q6-Q$5 -> 2.56 | Q24: =Q16-Q$15 -> 2.78 | R24: =S6-S$5 -> 0.98 | S24: =S16-S$15 -> 1.13 | T24: =U6-U$5 -> -0.1 | U24: =U16-U$15 -> 0 | V24: =W6-W$5 -> 1.94 | W24: =W16-W$15 -> 4.43
M25: ein Tor offen | N25: =O7-O$5 -> 40.38 | O25: =O17-O$15 -> 40.74 | P25: =Q7-Q$5 -> 58.91 | Q25: =Q17-Q$15 -> 62.12 | R25: =S7-S$5 -> 37.09 | S25: =S17-S$15 -> 39.16 | T25: =U7-U$5 -> 22.77 | U25: =U17-U$15 -> 24.08 | V25: =W7-W$5 -> 51.31 | W25: =W17-W$15 -> 87.02
M26: 2 Tore offen, eine Fassade | N26: =O8-O$5 -> 89.54 | O26: =O18-O$15 -> 89.67 | P26: =Q8-Q$5 -> 125.06 | Q26: =Q18-Q$15 -> 131.62 | R26: =S8-S$5 -> 81.62 | S26: =S18-S$15 -> 85.96 | T26: =U8-U$5 -> 42.81 | U26: =U18-U$15 -> 45.12 | V26: =W8-W$5 -> 89.03 | W26: =W18-W$15 -> 142.13
M27: 2 Tore offen, beide Fassaden | N27: =O9-O$5 -> 106.26 | O27: =O19-O$15 -> 137.45 | P27: =Q9-Q$5 -> 98.27 | Q27: =Q19-Q$15 -> 103.77 | R27: =S9-S$5 -> 60.68 | S27: =S19-S$15 -> 64.26 | T27: =U9-U$5 -> 40.64 | U27: =U19-U$15 -> 43.19 | V27: =W9-W$5 -> 83.26 | W27: =W19-W$15 -> 166.1
M28: 3 und mehr Tore offen | N28: =O10-O$5 -> 101.53 | O28: =O20-O$15 -> 127.07 | P28: =Q10-Q$5 -> 108.15 | Q28: =Q20-Q$15 -> 114.32 | R28: =S10-S$5 -> 65.27 | S28: =S20-S$15 -> 69.03 | T28: =U10-U$5 -> 48.73 | U28: =U20-U$15 -> 51.61 | V28: =W10-W$5 -> 104.93 | W28: =W20-W$15 -> 248.91

Sheet 6.4.1 Dauerlinie
B2: Dauerlinie/Percentile der Heizlast [in kW] | J2: Betrag des Stundengradienten
B3: Modell | C3: S/N | D3: S/N | E3: S/N | F3: O/W | G3: O/W | H3: O/W | J3: Modell | K3: S/N | L3: S/N | M3: S/N | N3: S/N | O3: O/W | P3: O/W | Q3: O/W | R3: O/W
C4: P99 | D4: P95 | E4: P50 | F4: P99 | G4: P95 | H4: P50 | K4: Median | L4: P95 | M4: P99 | N4: Max | O4: Median | P4: P95 | Q4: P99 | R4: Max
B5: AFN_E+ | C5: 52.54 | D5: 36.53 | E5: 14.39 | F5: 53.79 | G5: 37.11 | H5: 14.46 | J5: AFN_E+ | K5: 2.218 | L5: 17.49 | M5: 27.5 | N5: =MAX(Lastgradienten!F8:F5094) -> 53.698 | O5: 2.287 | P5: 18.54 | Q5: 31.83 | R5: =MAX(Lastgradienten!K8:K5094) -> 70.605
B6: DFR_BLAST | C6: 61.81 | D6: 43.68 | E6: 15.23 | F6: 64.07 | G6: 45.3 | H6: 15.42 | J6: DFR_BLAST | K6: 2.969 | L6: 21.98 | M6: 34.53 | N6: =MAX(Lastgradienten!G8:G5094) -> 61.711 | O6: 3.109 | P6: 23.08 | Q6: 36.18 | R6: =MAX(Lastgradienten!L8:L5094) -> 64.814
B7: DFR_DEFAULT | C7: 45.34 | D7: 33.21 | E7: 14.25 | F7: 46.79 | G7: 34.29 | H7: 14.4 | J7: DFR_DEFAULT | K7: 2.216 | L7: 14.49 | M7: 20.94 | N7: =MAX(Lastgradienten!H8:H5094) -> 36.355 | O7: 2.315 | P7: 15.23 | Q7: 22 | R7: =MAX(Lastgradienten!M8:M5094) -> 38.244
B8: DFR_DOE-2 | C8: 36.34 | D8: 26.82 | E8: 13.43 | F8: 37.39 | G8: 27.42 | H8: 13.59 | J8: DFR_DOE-2 | K8: 1.25 | L8: 11.49 | M8: 19.75 | N8: =MAX(Lastgradienten!I8:I5094) -> 65.499 | O8: 1.275 | P8: 11.87 | Q8: 20.7 | R8: =MAX(Lastgradienten!N8:N5094) -> 68.906
B9: WSOA | C9: 86.46 | D9: 45.35 | E9: 13.92 | F9: 146.43 | G9: 69.74 | H9: 14.47 | J9: WSOA | K9: 1.25 | L9: 29.57 | M9: 54.39 | N9: =MAX(Lastgradienten!J8:J5094) -> 196.021 | O9: 1.361 | P9: 52.21 | Q9: 112.24 | R9: =MAX(Lastgradienten!O8:O5094) -> 337.957
B10: Spanne_ges | C10: =MAX(C5:C9)-MIN(C5:C9) -> 50.12 | D10: =MAX(D5:D9)-MIN(D5:D9) -> 18.53 | E10: =MAX(E5:E9)-MIN(E5:E9) -> 1.8 | F10: =MAX(F5:F9)-MIN(F5:F9) -> 109.04 | G10: =MAX(G5:G9)-MIN(G5:G9) -> 42.32 | H10: =MAX(H5:H9)-MIN(H5:H9) -> 1.83 | J10: max/min | K10: =MAX(K5:K9)/MIN(K5:K9) -> 2.3752 | L10: =MAX(L5:L9)/MIN(L5:L9) -> 2.5735422 | M10: =MAX(M5:M9)/MIN(M5:M9) -> 2.7539241 | N10: =MAX(N5:N9)/MIN(N5:N9) -> 5.3918581 | O10: =MAX(O5:O9)/MIN(O5:O9) -> 2.4384314 | P10: =MAX(P5:P9)/MIN(P5:P9) -> 4.3984836 | Q10: =MAX(Q5:Q9)/MIN(Q5:Q9) -> 5.4222222 | R10: =MAX(R5:R9)/MIN(R5:R9) -> 8.8368633
B11: max/min | C11: =MAX(C5:C9)/MIN(C5:C9) -> 2.3791965 | D11: =MAX(D5:D9)/MIN(D5:D9) -> 1.6909023 | E11: =MAX(E5:E9)/MIN(E5:E9) -> 1.1340283 | F11: =MAX(F5:F9)/MIN(F5:F9) -> 3.9162878 | G11: =MAX(G5:G9)/MIN(G5:G9) -> 2.543399 | H11: =MAX(H5:H9)/MIN(H5:H9) -> 1.1346578

Sheet 6.4.2 Spitzenlasten
B2: Auswertung der Spitzenlasten | I2: Orientierung | J2: Modell | K2: Rang | L2: Stunde in der Heizperiode [h] | M2: Datum | N2: Uhrzeit | O2: Heizlast | P2: Aussentemp-eratur [°C] | Q2: Windgeschwindig-keit [m/s] | R2: Windrichtung | S2: Anteil Minuten Tor offen | T2: Anteil Minuten nur angedockt
B3: Modell | C3: S/N | D3: S/N | E3: O/W | F3: O/W | O3: [kW] | R3: [°]
C4: Top 10 | D4: Max | E4: Top 10 | F4: Max | I4: S/N | J4: AFN_E+ | K4: 1 | L4: 1131 | M4: 17.02. | N4: 0.125 | O4: 85.26 | P4: -12.4 | Q4: 0.5 | R4: 100 | S4: 0.383 | T4: 0.617
B5: AFN_E+ | C5: =AVERAGE(O4:O13) -> 74.526 | D5: =MAX(O4:O13) -> 85.26 | E5: =AVERAGE(O54:O63) -> 75.555 | F5: =MAX(O54:O63) -> 84.77 | I5: S/N | J5: AFN_E+ | K5: 2 | L5: 1107 | M5: 16.02. | N5: 0.125 | O5: 78.54 | P5: -9.59 | Q5: 0 | R5: 0 | S5: 0.3 | T5: 0.7
B6: DFR_BLAST | C6: =AVERAGE(O34:O43) -> 86.932 | D6: =MAX(O34:O43) -> 99.13 | E6: =AVERAGE(O84:O93) -> 90.461 | F6: =MAX(O84:O93) -> 103.34 | I6: S/N | J6: AFN_E+ | K6: 3 | L6: 1053 | M6: 13.02. | N6: 0.875 | O6: 78.24 | P6: -10.89 | Q6: 2.35 | R6: 95 | S6: 0.4 | T6: 0.6
B7: DFR_DEFAULT | C7: =AVERAGE(O24:O33) -> 60.274 | D7: =MAX(O24:O33) -> 67.81 | E7: =AVERAGE(O74:O83) -> 62.384 | F7: =MAX(O74:O83) -> 70.18 | I7: S/N | J7: AFN_E+ | K7: 4 | L7: 1035 | M7: 13.02. | N7: 0.125 | O7: 73.96 | P7: -13.47 | Q7: 0 | R7: 0 | S7: 0.267 | T7: 0.733
B8: DFR_DOE-2 | C8: =AVERAGE(O44:O53) -> 54.032 | D8: =MAX(O44:O53) -> 85.37 | E8: =AVERAGE(O94:O103) -> 56.356 | F8: =MAX(O94:O103) -> 89.65 | I8: S/N | J8: AFN_E+ | K8: 5 | L8: 1149 | M8: 17.02. | N8: 0.875 | O8: 73.16 | P8: -12.3 | Q8: 0 | R8: 0 | S8: 0.317 | T8: 0.683
B9: WSOA | C9: =AVERAGE(O14:O23) -> 155.283 | D9: =MAX(O14:O23) -> 223.98 | E9: =AVERAGE(O64:O73) -> 293.163 | F9: =MAX(O64:O73) -> 393.78 | I9: S/N | J9: AFN_E+ | K9: 6 | L9: 5086 | M9: 31.12. | N9: 0.91666667 | O9: 72.99 | P9: -9.49 | Q9: 1.5 | R9: 180 | S9: 0.317 | T9: 0.683
I10: S/N | J10: AFN_E+ | K10: 7 | L10: 1036 | M10: 13.02. | N10: 0.16666667 | O10: 72.46 | P10: -15.2 | Q10: 0 | R10: 0 | S10: 0.2 | T10: 0.717
B11: Zeitpunkt der Spitzenlasten | E11: Max | F11: S/N | I11: S/N | J11: AFN_E+ | K11: 8 | L11: 1156 | M11: 18.02. | N11: 0.16666667 | O11: 71.98 | P11: -15.71 | Q11: 0.25 | R11: 69 | S11: 0.183 | T11: 0.367
B12: Modell | C12: Stunde [h] | D12: T_außen [°C] | E12: u [m/s] | F12: Anteil Tor offen | I12: S/N | J12: AFN_E+ | K12: 9 | L12: 1197 | M12: 19.02. | N12: 0.875 | O12: 69.89 | P12: -9.41 | Q12: 1 | R12: 120 | S12: 0.317 | T12: 0.683
B13: AFN_E+ | C13: =L4 -> 1131 | D13: =P4 -> -12.4 | E13: =Q4 -> 0.5 | F13: =S4 -> 0.383 | I13: S/N | J13: AFN_E+ | K13: 10 | L13: 1153 | M13: 18.02. | N13: 0.041666667 | O13: 68.78 | P13: -15.01 | Q13: 0.76 | R13: 56 | S13: 0.2 | T13: 0.8
B14: DFR_BLAST | C14: =L34 -> 1131 | D14: =P34 -> -12.4 | E14: =Q34 -> 0.5 | F14: =S34 -> 0.383 | I14: S/N | J14: WSOA | K14: 1 | L14: 348 | M14: 15.01. | N14: 0.5 | O14: 223.98 | P14: 2.95 | Q14: 15.66 | R14: 240 | S14: 0.5 | T14: 0.5
B15: DFR_DEFAULT | C15: =L24 -> 1131 | D15: =P24 -> -12.4 | E15: =Q24 -> 0.5 | F15: =S24 -> 0.383 | I15: S/N | J15: WSOA | K15: 2 | L15: 508 | M15: 22.01. | N15: 0.16666667 | O15: 162.5 | P15: 0.02 | Q15: 4.42 | R15: 195 | S15: 0.333 | T15: 0.65
B16: DFR_DOE-2 | C16: =L44 -> 348 | D16: =P44 -> 2.95 | E16: =Q44 -> 15.66 | F16: =S44 -> 0.5 | I16: S/N | J16: WSOA | K16: 3 | L16: 626 | M16: 27.01. | N16: 0.083333333 | O16: 156.27 | P16: -6.1 | Q16: 3.1 | R16: 220 | S16: 0.35 | T16: 0.65
B17: WSOA | C17: =L14 -> 348 | D17: =P14 -> 2.95 | E17: =Q14 -> 15.66 | F17: =S14 -> 0.5 | I17: S/N | J17: WSOA | K17: 4 | L17: 650 | M17: 28.01. | N17: 0.083333333 | O17: 154.93 | P17: -10.29 | Q17: 2.04 | R17: 185 | S17: 0.283 | T17: 0.717
E18: Max | F18: O/W | I18: S/N | J18: WSOA | K18: 5 | L18: 459 | M18: 20.01. | N18: 0.125 | O18: 151.87 | P18: 3.4 | Q18: 13.75 | R18: 245 | S18: 0.25 | T18: 0.75
B19: Modell | C19: Stunde [h] | D19: T_außen [°C] | E19: u [m/s] | F19: Anteil Tor offen | I19: S/N | J19: WSOA | K19: 6 | L19: 315 | M19: 14.01. | N19: 0.125 | O19: 151.53 | P19: 4.85 | Q19: 12.59 | R19: 245 | S19: 0.35 | T19: 0.65
B20: AFN_E+ | C20: =L54 -> 1131 | D20: -12.4 | E20: 0.5 | F20: 0.383 | I20: S/N | J20: WSOA | K20: 7 | L20: 316 | M20: 14.01. | N20: 0.16666667 | O20: 146.67 | P20: 4.7 | Q20: 12.61 | R20: 245 | S20: 0.367 | T20: 0.617
B21: DFR_BLAST | C21: =L84 -> 1053 | D21: =P84 -> -10.89 | E21: =Q84 -> 2.35 | F21: =S84 -> 0.4 | I21: S/N | J21: WSOA | K21: 8 | L21: 531 | M21: 23.01. | N21: 0.125 | O21: 137.13 | P21: 1.21 | Q21: 4.35 | R21: 170 | S21: 0.283 | T21: 0.717
B22: DFR_DEFAULT | C22: =L74 -> 1131 | D22: -12.4 | E22: 0.5 | F22: 0.383 | I22: S/N | J22: WSOA | K22: 9 | L22: 458 | M22: 20.01. | N22: 0.083333333 | O22: 134.13 | P22: 3.4 | Q22: 13.5 | R22: 240 | S22: 0.217 | T22: 0.783
B23: DFR_DOE-2 | C23: 348 | D23: 2.95 | E23: 15.66 | F23: 0.5 | I23: S/N | J23: WSOA | K23: 10 | L23: 100 | M23: 05.01. | N23: 0.16666667 | O23: 133.82 | P23: -8.05 | Q23: 2.1 | R23: 200 | S23: 0.333 | T23: 0.667
B24: WSOA | C24: 348 | D24: 2.95 | E24: 15.66 | F24: 0.5 | I24: S/N | J24: DFR_DEFAULT | K24: 1 | L24: 1131 | M24: 17.02. | N24: 0.125 | O24: 67.81 | P24: -12.4 | Q24: 0.5 | R24: 100 | S24: 0.383 | T24: 0.617
I25: S/N | J25: DFR_DEFAULT | K25: 2 | L25: 1107 | M25: 16.02. | N25: 0.125 | O25: 64.88 | P25: -9.59 | Q25: 0 | R25: 0 | S25: 0.3 | T25: 0.7
B26: Zeitpunkt der Spitzenlasten | D26: Top 10 | E26: S/N | I26: S/N | J26: DFR_DEFAULT | K26: 3 | L26: 1053 | M26: 13.02. | N26: 0.875 | O26: 62.92 | P26: -10.89 | Q26: 2.35 | R26: 95 | S26: 0.4 | T26: 0.6
B27: Modell | C27: T_außen [°C] | D27: u [m/s] | E27: Anteil Tor offen | I27: S/N | J27: DFR_DEFAULT | K27: 4 | L27: 5086 | M27: 31.12. | N27: 0.91666667 | O27: 60.49 | P27: -9.49 | Q27: 1.5 | R27: 180 | S27: 0.317 | T27: 0.683
B28: AFN_E+ | C28: =AVERAGE(P4:P13) -> -12.347 | D28: =AVERAGE(Q4:Q13) -> 0.636 | E28: =AVERAGE(S4:S13) -> 0.2884 | I28: S/N | J28: DFR_DEFAULT | K28: 5 | L28: 1035 | M28: 13.02. | N28: 0.125 | O28: 59.66 | P28: -13.47 | Q28: 0 | R28: 0 | S28: 0.267 | T28: 0.733
B29: DFR_BLAST | C29: =AVERAGE(P34:P43) -> -10.965 | D29: =AVERAGE(Q34:Q43) -> 1.074 | E29: =AVERAGE(S34:S43) -> 0.3117 | I29: S/N | J29: DFR_DEFAULT | K29: 6 | L29: 1149 | M29: 17.02. | N29: 0.875 | O29: 58.41 | P29: -12.3 | Q29: 0 | R29: 0 | S29: 0.317 | T29: 0.683
B30: DFR_DEFAULT | C30: =AVERAGE(P24:P33) -> -11.875 | D30: =AVERAGE(Q24:Q33) -> 0.764 | E30: =AVERAGE(S24:S33) -> 0.2967 | I30: S/N | J30: DFR_DEFAULT | K30: 7 | L30: 1036 | M30: 13.02. | N30: 0.16666667 | O30: 57.93 | P30: -15.2 | Q30: 0 | R30: 0 | S30: 0.2 | T30: 0.717
B31: DFR_DOE-2 | C31: =AVERAGE(P44:P53) -> 3.807 | D31: =AVERAGE(Q44:Q53) -> 12.991 | E31: =AVERAGE(S44:S53) -> 0.3118 | I31: S/N | J31: DFR_DEFAULT | K31: 8 | L31: 1156 | M31: 18.02. | N31: 0.16666667 | O31: 57.65 | P31: -15.71 | Q31: 0.25 | R31: 69 | S31: 0.183 | T31: 0.367
B32: WSOA | C32: =AVERAGE(P14:P23) -> -0.391 | D32: =AVERAGE(Q14:Q23) -> 8.412 | E32: =AVERAGE(S14:S23) -> 0.3266 | I32: S/N | J32: DFR_DEFAULT | K32: 9 | L32: 1197 | M32: 19.02. | N32: 0.875 | O32: 57.47 | P32: -9.41 | Q32: 1 | R32: 120 | S32: 0.317 | T32: 0.683
D33: Top 10 | E33: O/W | I33: S/N | J33: DFR_DEFAULT | K33: 10 | L33: 650 | M33: 28.01. | N33: 0.083333333 | O33: 55.52 | P33: -10.29 | Q33: 2.04 | R33: 185 | S33: 0.283 | T33: 0.717
B34: Modell | C34: T_außen [°C] | D34: u [m/s] | E34: Anteil Tor offen | I34: S/N | J34: DFR_BLAST | K34: 1 | L34: 1131 | M34: 17.02. | N34: 0.125 | O34: 99.13 | P34: -12.4 | Q34: 0.5 | R34: 100 | S34: 0.383 | T34: 0.617
B35: AFN_E+ | C35: =AVERAGE(P54:P63) -> -7.911 | D35: =AVERAGE(Q54:Q63) -> 3.258 | E35: =AVERAGE(S54:S63) -> 0.3484 | I35: S/N | J35: DFR_BLAST | K35: 2 | L35: 1053 | M35: 13.02. | N35: 0.875 | O35: 98.92 | P35: -10.89 | Q35: 2.35 | R35: 95 | S35: 0.4 | T35: 0.6
B36: DFR_BLAST | C36: =AVERAGE(P84:P93) -> -10.965 | D36: =AVERAGE(Q84:Q93) -> 1.074 | E36: =AVERAGE(S84:S93) -> 0.3117 | I36: S/N | J36: DFR_BLAST | K36: 3 | L36: 1107 | M36: 16.02. | N36: 0.125 | O36: 87.91 | P36: -9.59 | Q36: 0 | R36: 0 | S36: 0.3 | T36: 0.7
B37: DFR_DEFAULT | C37: =AVERAGE(P74:P83) -> -11.875 | D37: =AVERAGE(Q74:Q83) -> 0.764 | E37: =AVERAGE(S74:S83) -> 0.2967 | I37: S/N | J37: DFR_BLAST | K37: 4 | L37: 5086 | M37: 31.12. | N37: 0.91666667 | O37: 87.78 | P37: -9.49 | Q37: 1.5 | R37: 180 | S37: 0.317 | T37: 0.683
B38: DFR_DOE-2 | C38: =AVERAGE(P94:P103) -> 3.813 | D38: =AVERAGE(Q94:Q103) -> 13.199 | E38: =AVERAGE(S94:S103) -> 0.3285 | I38: S/N | J38: DFR_BLAST | K38: 5 | L38: 1035 | M38: 13.02. | N38: 0.125 | O38: 83.37 | P38: -13.47 | Q38: 0 | R38: 0 | S38: 0.267 | T38: 0.733
B39: WSOA | C39: =AVERAGE(P64:P73) -> 2.625 | D39: =AVERAGE(Q64:Q73) -> 11.006 | E39: =AVERAGE(S64:S73) -> 0.3383 | I39: S/N | J39: DFR_BLAST | K39: 6 | L39: 626 | M39: 27.01. | N39: 0.083333333 | O39: 83.19 | P39: -6.1 | Q39: 3.1 | R39: 220 | S39: 0.35 | T39: 0.65
I40: S/N | J40: DFR_BLAST | K40: 7 | L40: 1197 | M40: 19.02. | N40: 0.875 | O40: 82.59 | P40: -9.41 | Q40: 1 | R40: 120 | S40: 0.317 | T40: 0.683
I41: S/N | J41: DFR_BLAST | K41: 8 | L41: 1149 | M41: 17.02. | N41: 0.875 | O41: 82.56 | P41: -12.3 | Q41: 0 | R41: 0 | S41: 0.317 | T41: 0.683
...

Sheet 6.4.3 Formdistanz
B1: Paarweiser Abstand der Lastgänge, zerlegt in Niveau, Amplitude und Timing
B2: RMSD²(a,b) = (P̄a − P̄b)² + (σa − σb)² + 2·σa·σb·(1 − r_ab) = Niveau² + Amplitude² + Timing²
B4: Orientierung | C4: Modell a | D4: Modell b | E4: Mittelwert | G4: Standardabweichung | I4: Korrelation | J4: Niveau | K4: Amplitude | L4: Timing | M4: RMSD | N4: Niveau | O4: Amplitude | P4: Timing | Q4: CV(RMSD) | R4: RMSD direkt | S4: Kontrolle
E5: P̄a [kW] | F5: P̄b [kW] | G5: σa [kW] | H5: σb [kW] | I5: r_ab [-] | J5: [kW] | K5: [kW] | L5: [kW] | M5: [kW] | N5: [%] | O5: [%] | P5: [%] | Q5: [%] | R5: [kW] | S5: [kW]
B6: S/N | C6: AFN_E+ | D6: DFR_BLAST | E6: =Heizlasten!G8 -> 15.815081 | F6: =Heizlasten!H8 -> 17.95408 | G6: =Heizlasten!G9 -> 11.102868 | H6: =Heizlasten!H9 -> 13.155175 | I6: =CORREL(Heizlasten!G11:G5098,Heizlasten!H11:H5098) -> 0.98277478 | J6: =ABS(E6-F6) -> 2.1389989 | K6: =ABS(G6-H6) -> 2.0523062 | L6: =SQRT(2*G6*H6*(1-I6)) -> 2.2431757 | M6: =SQRT(J6^2+K6^2+L6^2) -> 3.7174069 | N6: =J6^2/$M6^2 -> 0.33108608 | O6: =K6^2/$M6^2 -> 0.30479239 | P6: =L6^2/$M6^2 -> 0.36412153 | Q6: =M6/((E6+F6)/2) -> 0.22016579 | R6: =SQRT(SUMXMY2(Heizlasten!G11:G5098,Heizlasten!H11:H5098)/Heizlasten!G5) -> 3.7174069 | S6: =M6-R6 -> 3.5216274e-13
B7: S/N | C7: AFN_E+ | D7: DFR_DEFAULT | E7: =Heizlasten!G8 -> 15.815081 | F7: =Heizlasten!I8 -> 15.148727 | G7: =Heizlasten!G9 -> 11.102868 | H7: =Heizlasten!I9 -> 9.761662 | I7: =CORREL(Heizlasten!G11:G5098,Heizlasten!I11:I5098) -> 0.98298294 | J7: =ABS(E7-F7) -> 0.66635413 | K7: =ABS(G7-H7) -> 1.3412063 | L7: =SQRT(2*G7*H7*(1-I7)) -> 1.9205994 | M7: =SQRT(J7^2+K7^2+L7^2) -> 2.4354803 | N7: =J7^2/$M7^2 -> 0.074858469 | O7: =K7^2/$M7^2 -> 0.30326477 | P7: =L7^2/$M7^2 -> 0.62187677 | Q7: =M7/((E7+F7)/2) -> 0.15731142 | R7: =SQRT(SUMXMY2(Heizlasten!G11:G5098,Heizlasten!I11:I5098)/Heizlasten!G5) -> 2.4354803 | S7: =M7-R7 -> 3.8147263e-13
B8: S/N | C8: AFN_E+ | D8: DFR_DOE-2 | E8: =Heizlasten!G8 -> 15.815081 | F8: =Heizlasten!J8 -> 13.248208 | G8: =Heizlasten!G9 -> 11.102868 | H8: =Heizlasten!J9 -> 8.01994 | I8: =CORREL(Heizlasten!G11:G5098,Heizlasten!J11:J5098) -> 0.8475904 | J8: =ABS(E8-F8) -> 2.5668724 | K8: =ABS(G8-H8) -> 3.0829283 | L8: =SQRT(2*G8*H8*(1-I8)) -> 5.2098392 | M8: =SQRT(J8^2+K8^2+L8^2) -> 6.5753863 | N8: =J8^2/$M8^2 -> 0.15239335 | O8: =K8^2/$M8^2 -> 0.21982865 | P8: =L8^2/$M8^2 -> 0.62777799 | Q8: =M8/((E8+F8)/2) -> 0.45248741 | R8: =SQRT(SUMXMY2(Heizlasten!G11:G5098,Heizlasten!J11:J5098)/Heizlasten!G5) -> 6.5753863 | S8: =M8-R8 -> 7.1054274e-14
B9: S/N | C9: AFN_E+ | D9: WSOA | E9: =Heizlasten!G8 -> 15.815081 | F9: =Heizlasten!K8 -> 16.845304 | G9: =Heizlasten!G9 -> 11.102868 | H9: =Heizlasten!K9 -> 16.193905 | I9: =CORREL(Heizlasten!G11:G5098,Heizlasten!K11:K5098) -> 0.61778713 | J9: =ABS(E9-F9) -> 1.0302236 | K9: =ABS(G9-H9) -> 5.0910363 | L9: =SQRT(2*G9*H9*(1-I9)) -> 11.723601 | M9: =SQRT(J9^2+K9^2+L9^2) -> 12.822747 | N9: =J9^2/$M9^2 -> 0.0064550682 | O9: =K9^2/$M9^2 -> 0.15763413 | P9: =L9^2/$M9^2 -> 0.8359108 | Q9: =M9/((E9+F9)/2) -> 0.78521712 | R9: =SQRT(SUMXMY2(Heizlasten!G11:G5098,Heizlasten!K11:K5098)/Heizlasten!G5) -> 12.822747 | S9: =M9-R9 -> -2.6645353e-14
B10: S/N | C10: DFR_BLAST | D10: DFR_DEFAULT | E10: =Heizlasten!H8 -> 17.95408 | F10: =Heizlasten!I8 -> 15.148727 | G10: =Heizlasten!H9 -> 13.155175 | H10: =Heizlasten!I9 -> 9.761662 | I10: =CORREL(Heizlasten!H11:H5098,Heizlasten!I11:I5098) -> 0.9716111 | J10: =ABS(E10-F10) -> 2.805353 | K10: =ABS(G10-H10) -> 3.3935126 | L10: =SQRT(2*G10*H10*(1-I10)) -> 2.7002219 | M10: =SQRT(J10^2+K10^2+L10^2) -> 5.1649909 | N10: =J10^2/$M10^2 -> 0.29500944 | O10: =K10^2/$M10^2 -> 0.43167788 | P10: =L10^2/$M10^2 -> 0.27331267 | Q10: =M10/((E10+F10)/2) -> 0.31205759 | R10: =SQRT(SUMXMY2(Heizlasten!H11:H5098,Heizlasten!I11:I5098)/Heizlasten!G5) -> 5.1649909 | S10: =M10-R10 -> -3.5527137e-14
B11: S/N | C11: DFR_BLAST | D11: DFR_DOE-2 | E11: =Heizlasten!H8 -> 17.95408 | F11: =Heizlasten!J8 -> 13.248208 | G11: =Heizlasten!H9 -> 13.155175 | H11: =Heizlasten!J9 -> 8.01994 | I11: =CORREL(Heizlasten!H11:H5098,Heizlasten!J11:J5098) -> 0.85065908 | J11: =ABS(E11-F11) -> 4.7058713 | K11: =ABS(G11-H11) -> 5.1352345 | L11: =SQRT(2*G11*H11*(1-I11)) -> 5.6135588 | M11: =SQRT(J11^2+K11^2+L11^2) -> 8.9458315 | N11: =J11^2/$M11^2 -> 0.27671881 | O11: =K11^2/$M11^2 -> 0.32951799 | P11: =L11^2/$M11^2 -> 0.3937632 | Q11: =M11/((E11+F11)/2) -> 0.57340868 | R11: =SQRT(SUMXMY2(Heizlasten!H11:H5098,Heizlasten!J11:J5098)/Heizlasten!G5) -> 8.9458315 | S11: =M11-R11 -> -8.7041485e-14
B12: S/N | C12: DFR_BLAST | D12: WSOA | E12: =Heizlasten!H8 -> 17.95408 | F12: =Heizlasten!K8 -> 16.845304 | G12: =Heizlasten!H9 -> 13.155175 | H12: =Heizlasten!K9 -> 16.193905 | I12: =CORREL(Heizlasten!H11:H5098,Heizlasten!K11:K5098) -> 0.63671413 | J12: =ABS(E12-F12) -> 1.1087753 | K12: =ABS(G12-H12) -> 3.0387301 | L12: =SQRT(2*G12*H12*(1-I12)) -> 12.441231 | M12: =SQRT(J12^2+K12^2+L12^2) -> 12.854862 | N12: =J12^2/$M12^2 -> 0.0074396457 | O12: =K12^2/$M12^2 -> 0.055879098 | P12: =L12^2/$M12^2 -> 0.93668126 | Q12: =M12/((E12+F12)/2) -> 0.73879827 | R12: =SQRT(SUMXMY2(Heizlasten!H11:H5098,Heizlasten!K11:K5098)/Heizlasten!G5) -> 12.854862 | S12: =M12-R12 -> -5.8619776e-14
B13: S/N | C13: DFR_DEFAULT | D13: DFR_DOE-2 | E13: =Heizlasten!I8 -> 15.148727 | F13: =Heizlasten!J8 -> 13.248208 | G13: =Heizlasten!I9 -> 9.761662 | H13: =Heizlasten!J9 -> 8.01994 | I13: =CORREL(Heizlasten!I11:I5098,Heizlasten!J11:J5098) -> 0.84059002 | J13: =ABS(E13-F13) -> 1.9005183 | K13: =ABS(G13-H13) -> 1.7417219 | L13: =SQRT(2*G13*H13*(1-I13)) -> 4.9959742 | M13: =SQRT(J13^2+K13^2+L13^2) -> 5.6218612 | N13: =J13^2/$M13^2 -> 0.11428359 | O13: =K13^2/$M13^2 -> 0.095983679 | P13: =L13^2/$M13^2 -> 0.78973273 | Q13: =M13/((E13+F13)/2) -> 0.39594845 | R13: =SQRT(SUMXMY2(Heizlasten!I11:I5098,Heizlasten!J11:J5098)/Heizlasten!G5) -> 5.6218612 | S13: =M13-R13 -> -2.1316282e-14
B14: S/N | C14: DFR_DEFAULT | D14: WSOA | E14: =Heizlasten!I8 -> 15.148727 | F14: =Heizlasten!K8 -> 16.845304 | G14: =Heizlasten!I9 -> 9.761662 | H14: =Heizlasten!K9 -> 16.193905 | I14: =CORREL(Heizlasten!I11:I5098,Heizlasten!K11:K5098) -> 0.59107542 | J14: =ABS(E14-F14) -> 1.6965777 | K14: =ABS(G14-H14) -> 6.4322426 | L14: =SQRT(2*G14*H14*(1-I14)) -> 11.370362 | M14: =SQRT(J14^2+K14^2+L14^2) -> 13.173354 | N14: =J14^2/$M14^2 -> 0.016586502 | O14: =K14^2/$M14^2 -> 0.23841421 | P14: =L14^2/$M14^2 -> 0.74499928 | Q14: =M14/((E14+F14)/2) -> 0.8234882 | R14: =SQRT(SUMXMY2(Heizlasten!I11:I5098,Heizlasten!K11:K5098)/Heizlasten!G5) -> 13.173354 | S14: =M14-R14 -> -1.7763568e-14
B15: S/N | C15: DFR_DOE-2 | D15: WSOA | E15: =Heizlasten!J8 -> 13.248208 | F15: =Heizlasten!K8 -> 16.845304 | G15: =Heizlasten!J9 -> 8.01994 | H15: =Heizlasten!K9 -> 16.193905 | I15: =CORREL(Heizlasten!J11:J5098,Heizlasten!K11:K5098) -> 0.68289637 | J15: =ABS(E15-F15) -> 3.597096 | K15: =ABS(G15-H15) -> 8.1739646 | L15: =SQRT(2*G15*H15*(1-I15)) -> 9.0756336 | M15: =SQRT(J15^2+K15^2+L15^2) -> 12.732632 | N15: =J15^2/$M15^2 -> 0.079811904 | O15: =K15^2/$M15^2 -> 0.41212515 | P15: =L15^2/$M15^2 -> 0.50806295 | Q15: =M15/((E15+F15)/2) -> 0.84620445 | R15: =SQRT(SUMXMY2(Heizlasten!J11:J5098,Heizlasten!K11:K5098)/Heizlasten!G5) -> 12.732632 | S15: =M15-R15 -> 2.1316282e-14
B16: O/W | C16: AFN_E+ | D16: DFR_BLAST | E16: =Heizlasten!L8 -> 15.989831 | F16: =Heizlasten!M8 -> 18.417675 | G16: =Heizlasten!L9 -> 11.248832 | H16: =Heizlasten!M9 -> 13.654963 | I16: =CORREL(Heizlasten!L11:L5098,Heizlasten!M11:M5098) -> 0.97767738 | J16: =ABS(E16-F16) -> 2.4278435 | K16: =ABS(G16-H16) -> 2.4061306 | L16: =SQRT(2*G16*H16*(1-I16)) -> 2.6187051 | M16: =SQRT(J16^2+K16^2+L16^2) -> 4.3059848 | N16: =J16^2/$M16^2 -> 0.3179043 | O16: =K16^2/$M16^2 -> 0.31224351 | P16: =L16^2/$M16^2 -> 0.3698522 | Q16: =M16/((E16+F16)/2) -> 0.25029334 | R16: =SQRT(SUMXMY2(Heizlasten!L11:L5098,Heizlasten!M11:M5098)/Heizlasten!G5) -> 4.3059848 | S16: =M16-R16 -> -4.3520743e-14
B17: O/W | C17: AFN_E+ | D17: DFR_DEFAULT | E17: =Heizlasten!L8 -> 15.989831 | F17: =Heizlasten!N8 -> 15.46605 | G17: =Heizlasten!L9 -> 11.248832 | H17: =Heizlasten!N9 -> 10.042866 | I17: =CORREL(Heizlasten!L11:L5098,Heizlasten!N11:N5098) -> 0.96728838 | J17: =ABS(E17-F17) -> 0.52378088 | K17: =ABS(G17-H17) -> 1.2059659 | L17: =SQRT(2*G17*H17*(1-I17)) -> 2.7186206 | M17: =SQRT(J17^2+K17^2+L17^2) -> 3.0198673 | N17: =J17^2/$M17^2 -> 0.030083168 | O17: =K17^2/$M17^2 -> 0.15947564 | P17: =L17^2/$M17^2 -> 0.81044119 | Q17: =M17/((E17+F17)/2) -> 0.19200653 | R17: =SQRT(SUMXMY2(Heizlasten!L11:L5098,Heizlasten!N11:N5098)/Heizlasten!G5) -> 3.0198673 | S17: =M17-R17 -> 3.0286884e-13
B18: O/W | C18: AFN_E+ | D18: DFR_DOE-2 | E18: =Heizlasten!L8 -> 15.989831 | F18: =Heizlasten!O8 -> 13.466245 | G18: =Heizlasten!L9 -> 11.248832 | H18: =Heizlasten!O9 -> 8.2070494 | I18: =CORREL(Heizlasten!L11:L5098,Heizlasten!O11:O5098) -> 0.85788711 | J18: =ABS(E18-F18) -> 2.523586 | K18: =ABS(G18-H18) -> 3.041783 | L18: =SQRT(2*G18*H18*(1-I18)) -> 5.1224647 | M18: =SQRT(J18^2+K18^2+L18^2) -> 6.4699749 | N18: =J18^2/$M18^2 -> 0.15213566 | O18: =K18^2/$M18^2 -> 0.22103002 | P18: =L18^2/$M18^2 -> 0.62683432 | Q18: =M18/((E18+F18)/2) -> 0.43929645 | R18: =SQRT(SUMXMY2(Heizlasten!L11:L5098,Heizlasten!O11:O5098)/Heizlasten!G5) -> 6.4699749 | S18: =M18-R18 -> -5.9507954e-14
B19: O/W | C19: AFN_E+ | D19: WSOA | E19: =Heizlasten!L8 -> 15.989831 | F19: =Heizlasten!P8 -> 21.442418 | G19: =Heizlasten!L9 -> 11.248832 | H19: =Heizlasten!P9 -> 28.025104 | I19: =CORREL(Heizlasten!L11:L5098,Heizlasten!P11:P5098) -> 0.47757689 | J19: =ABS(E19-F19) -> 5.4525868 | K19: =ABS(G19-H19) -> 16.776272 | L19: =SQRT(2*G19*H19*(1-I19)) -> 18.149035 | M19: =SQRT(J19^2+K19^2+L19^2) -> 25.309315 | N19: =J19^2/$M19^2 -> 0.046413506 | O19: =K19^2/$M19^2 -> 0.4393697 | P19: =L19^2/$M19^2 -> 0.5142168 | Q19: =M19/((E19+F19)/2) -> 1.3522733 | R19: =SQRT(SUMXMY2(Heizlasten!L11:L5098,Heizlasten!P11:P5098)/Heizlasten!G5) -> 25.309315 | S19: =M19-R19 -> -9.9475983e-14
B20: O/W | C20: DFR_BLAST | D20: DFR_DEFAULT | E20: =Heizlasten!M8 -> 18.417675 | F20: =Heizlasten!N8 -> 15.46605 | G20: =Heizlasten!M9 -> 13.654963 | H20: =Heizlasten!N9 -> 10.042866 | I20: =CORREL(Heizlasten!M11:M5098,Heizlasten!N11:N5098) -> 0.97166901 | J20: =ABS(E20-F20) -> 2.9516244 | K20: =ABS(G20-H20) -> 3.6120965 | L20: =SQRT(2*G20*H20*(1-I20)) -> 2.7875329 | M20: =SQRT(J20^2+K20^2+L20^2) -> 5.4341207 | N20: =J20^2/$M20^2 -> 0.29502826 | O20: =K20^2/$M20^2 -> 0.44183502 | P20: =L20^2/$M20^2 -> 0.26313672 | Q20: =M20/((E20+F20)/2) -> 0.32075108 | R20: =SQRT(SUMXMY2(Heizlasten!M11:M5098,Heizlasten!N11:N5098)/Heizlasten!G5) -> 5.4341207 | S20: =M20-R20 -> 1.5276669e-13
B21: O/W | C21: DFR_BLAST | D21: DFR_DOE-2 | E21: =Heizlasten!M8 -> 18.417675 | F21: =Heizlasten!O8 -> 13.466245 | G21: =Heizlasten!M9 -> 13.654963 | H21: =Heizlasten!O9 -> 8.2070494 | I21: =CORREL(Heizlasten!M11:M5098,Heizlasten!O11:O5098) -> 0.84660712 | J21: =ABS(E21-F21) -> 4.9514295 | K21: =ABS(G21-H21) -> 5.4479136 | L21: =SQRT(2*G21*H21*(1-I21)) -> 5.8634927 | M21: =SQRT(J21^2+K21^2+L21^2) -> 9.4115335 | N21: =J21^2/$M21^2 -> 0.27678364 | O21: =K21^2/$M21^2 -> 0.33507315 | P21: =L21^2/$M21^2 -> 0.38814321 | Q21: =M21/((E21+F21)/2) -> 0.59036238 | R21: =SQRT(SUMXMY2(Heizlasten!M11:M5098,Heizlasten!O11:O5098)/Heizlasten!G5) -> 9.4115335 | S21: =M21-R21 -> -1.0125234e-13
B22: O/W | C22: DFR_BLAST | D22: WSOA | E22: =Heizlasten!M8 -> 18.417675 | F22: =Heizlasten!P8 -> 21.442418 | G22: =Heizlasten!M9 -> 13.654963 | H22: =Heizlasten!P9 -> 28.025104 | I22: =CORREL(Heizlasten!M11:M5098,Heizlasten!P11:P5098) -> 0.49596307 | J22: =ABS(E22-F22) -> 3.0247433 | K22: =ABS(G22-H22) -> 14.370141 | L22: =SQRT(2*G22*H22*(1-I22)) -> 19.641066 | M22: =SQRT(J22^2+K22^2+L22^2) -> 24.523896 | N22: =J22^2/$M22^2 -> 0.015212412 | O22: =K22^2/$M22^2 -> 0.34335479 | P22: =L22^2/$M22^2 -> 0.6414328 | Q22: =M22/((E22+F22)/2) -> 1.2304987 | R22: =SQRT(SUMXMY2(Heizlasten!M11:M5098,Heizlasten!P11:P5098)/Heizlasten!G5) -> 24.523896 | S22: =M22-R22 -> -4.2632564e-14
B23: O/W | C23: DFR_DEFAULT | D23: DFR_DOE-2 | E23: =Heizlasten!N8 -> 15.46605 | F23: =Heizlasten!O8 -> 13.466245 | G23: =Heizlasten!N9 -> 10.042866 | H23: =Heizlasten!O9 -> 8.2070494 | I23: =CORREL(Heizlasten!N11:N5098,Heizlasten!O11:O5098) -> 0.83249218 | J23: =ABS(E23-F23) -> 1.9998051 | K23: =ABS(G23-H23) -> 1.835817 | L23: =SQRT(2*G23*H23*(1-I23)) -> 5.2547845 | M23: =SQRT(J23^2+K23^2+L23^2) -> 5.9145756 | N23: =J23^2/$M23^2 -> 0.11432156 | O23: =K23^2/$M23^2 -> 0.096341104 | P23: =L23^2/$M23^2 -> 0.78933733 | Q23: =M23/((E23+F23)/2) -> 0.40885629 | R23: =SQRT(SUMXMY2(Heizlasten!N11:N5098,Heizlasten!O11:O5098)/Heizlasten!G5) -> 5.9145756 | S23: =M23-R23 -> 1.5276669e-13
B24: O/W | C24: DFR_DEFAULT | D24: WSOA | E24: =Heizlasten!N8 -> 15.46605 | F24: =Heizlasten!P8 -> 21.442418 | G24: =Heizlasten!N9 -> 10.042866 | H24: =Heizlasten!P9 -> 28.025104 | I24: =CORREL(Heizlasten!N11:N5098,Heizlasten!P11:P5098) -> 0.388883 | J24: =ABS(E24-F24) -> 5.9763677 | K24: =ABS(G24-H24) -> 17.982237 | L24: =SQRT(2*G24*H24*(1-I24)) -> 18.547255 | M24: =SQRT(J24^2+K24^2+L24^2) -> 26.515627 | N24: =J24^2/$M24^2 -> 0.050800829 | O24: =K24^2/$M24^2 -> 0.45992142 | P24: =L24^2/$M24^2 -> 0.48927775 | Q24: =M24/((E24+F24)/2) -> 1.4368316 | R24: =SQRT(SUMXMY2(Heizlasten!N11:N5098,Heizlasten!P11:P5098)/Heizlasten!G5) -> 26.515627 | S24: =M24-R24 -> -5.6843419e-14
B25: O/W | C25: DFR_DOE-2 | D25: WSOA | E25: =Heizlasten!O8 -> 13.466245 | F25: =Heizlasten!P8 -> 21.442418 | G25: =Heizlasten!O9 -> 8.2070494 | H25: =Heizlasten!P9 -> 28.025104 | I25: =CORREL(Heizlasten!O11:O5098,Heizlasten!P11:P5098) -> 0.62148514 | J25: =ABS(E25-F25) -> 7.9761727 | K25: =ABS(G25-H25) -> 19.818055 | L25: =SQRT(2*G25*H25*(1-I25)) -> 13.195432 | M25: =SQRT(J25^2+K25^2+L25^2) -> 25.10964 | N25: =J25^2/$M25^2 -> 0.10090394 | O25: =K25^2/$M25^2 -> 0.62293259 | P25: =L25^2/$M25^2 -> 0.27616347 | Q25: =M25/((E25+F25)/2) -> 1.4385908 | R25: =SQRT(SUMXMY2(Heizlasten!O11:O5098,Heizlasten!P11:P5098)/Heizlasten!G5) -> 25.10964 | S25: =M25-R25 -> -5.6843419e-14
B27: Formdistanz der Lastgänge [%] — jeder Lastgang auf seinen eigenen Mittelwert normiert
B28: Formel je Zelle: √( Σ (Pa(t)/P̄a − Pb(t)/P̄b)² / n ). Unabhängig vom kalibrierten Leistungsniveau.
B30: S/N | C30: AFN_E+ | D30: DFR_BLAST | E30: DFR_DEFAULT | F30: DFR_DOE-2 | G30: WSOA | I30: O/W | J30: AFN_E+ | K30: DFR_BLAST | L30: DFR_DEFAULT | M30: DFR_DOE-2 | N30: WSOA
B31: AFN_E+ | C31: - | D31: {=SQRT(SUMPRODUCT((Heizlasten!G11:G5098/Heizlasten!G8-Heizlasten!H11:H5098/Heizlasten!H8)^2)/Heizlasten!G5)} -> 0.13660802 | E31: {=SQRT(SUMPRODUCT((Heizlasten!G11:G5098/Heizlasten!G8-Heizlasten!I11:I5098/Heizlasten!I8)^2)/Heizlasten!G5)} -> 0.13682368 | F31: {=SQRT(SUMPRODUCT((Heizlasten!G11:G5098/Heizlasten!G8-Heizlasten!J11:J5098/Heizlasten!J8)^2)/Heizlasten!G5)} -> 0.37268268 | G31: {=SQRT(SUMPRODUCT((Heizlasten!G11:G5098/Heizlasten!G8-Heizlasten!K11:K5098/Heizlasten!K8)^2)/Heizlasten!G5)} -> 0.76363433 | I31: AFN_E+ | J31: - | K31: {=SQRT(SUMPRODUCT((Heizlasten!L11:L5098/Heizlasten!L8-Heizlasten!M11:M5098/Heizlasten!M8)^2)/Heizlasten!L5)} -> 0.15723505 | L31: {=SQRT(SUMPRODUCT((Heizlasten!L11:L5098/Heizlasten!L8-Heizlasten!N11:N5098/Heizlasten!N8)^2)/Heizlasten!L5)} -> 0.18115917 | M31: {=SQRT(SUMPRODUCT((Heizlasten!L11:L5098/Heizlasten!L8-Heizlasten!O11:O5098/Heizlasten!O8)^2)/Heizlasten!L5)} -> 0.36153338 | N31: {=SQRT(SUMPRODUCT((Heizlasten!L11:L5098/Heizlasten!L8-Heizlasten!P11:P5098/Heizlasten!P8)^2)/Heizlasten!L5)} -> 1.151047
B32: DFR_BLAST | C32: {=SQRT(SUMPRODUCT((Heizlasten!G11:G5098/Heizlasten!G8-Heizlasten!H11:H5098/Heizlasten!H8)^2)/Heizlasten!G5)} -> 0.13660802 | D32: - | E32: {=SQRT(SUMPRODUCT((Heizlasten!H11:H5098/Heizlasten!H8-Heizlasten!I11:I5098/Heizlasten!I8)^2)/Heizlasten!G5)} -> 0.18603449 | F32: {=SQRT(SUMPRODUCT((Heizlasten!H11:H5098/Heizlasten!H8-Heizlasten!J11:J5098/Heizlasten!J8)^2)/Heizlasten!G5)} -> 0.38561681 | G32: {=SQRT(SUMPRODUCT((Heizlasten!H11:H5098/Heizlasten!H8-Heizlasten!K11:K5098/Heizlasten!K8)^2)/Heizlasten!G5)} -> 0.75103122 | I32: DFR_BLAST | J32: {=SQRT(SUMPRODUCT((Heizlasten!L11:L5098/Heizlasten!L8-Heizlasten!M11:M5098/Heizlasten!M8)^2)/Heizlasten!L5)} -> 0.15723505 | K32: - | L32: {=SQRT(SUMPRODUCT((Heizlasten!N11:N5098/Heizlasten!N8-Heizlasten!M11:M5098/Heizlasten!M8)^2)/Heizlasten!L5)} -> 0.18908512 | M32: {=SQRT(SUMPRODUCT((Heizlasten!M11:M5098/Heizlasten!M8-Heizlasten!O11:O5098/Heizlasten!O8)^2)/Heizlasten!L5)} -> 0.39501024 | N32: {=SQRT(SUMPRODUCT((Heizlasten!P11:P5098/Heizlasten!P8-Heizlasten!M11:M5098/Heizlasten!M8)^2)/Heizlasten!L5)} -> 1.1387387
B33: DFR_DEFAULT | C33: {=SQRT(SUMPRODUCT((Heizlasten!G11:G5098/Heizlasten!G8-Heizlasten!I11:I5098/Heizlasten!I8)^2)/Heizlasten!G5)} -> 0.13682368 | D33: {=SQRT(SUMPRODUCT((Heizlasten!H11:H5098/Heizlasten!H8-Heizlasten!I11:I5098/Heizlasten!I8)^2)/Heizlasten!G5)} -> 0.18603449 | E33: - | F33: {=SQRT(SUMPRODUCT((Heizlasten!I11:I5098/Heizlasten!I8-Heizlasten!J11:J5098/Heizlasten!J8)^2)/Heizlasten!G5)} -> 0.35481084 | G33: {=SQRT(SUMPRODUCT((Heizlasten!I11:I5098/Heizlasten!I8-Heizlasten!K11:K5098/Heizlasten!K8)^2)/Heizlasten!G5)} -> 0.77915689 | I33: DFR_DEFAULT | J33: {=SQRT(SUMPRODUCT((Heizlasten!L11:L5098/Heizlasten!L8-Heizlasten!N11:N5098/Heizlasten!N8)^2)/Heizlasten!L5)} -> 0.18115917 | K33: {=SQRT(SUMPRODUCT((Heizlasten!N11:N5098/Heizlasten!N8-Heizlasten!M11:M5098/Heizlasten!M8)^2)/Heizlasten!L5)} -> 0.18908512 | L33: - | M33: {=SQRT(SUMPRODUCT((Heizlasten!N11:N5098/Heizlasten!N8-Heizlasten!O11:O5098/Heizlasten!O8)^2)/Heizlasten!L5)} -> 0.36629695 | N33: {=SQRT(SUMPRODUCT((Heizlasten!P11:P5098/Heizlasten!P8-Heizlasten!N11:N5098/Heizlasten!N8)^2)/Heizlasten!L5)} -> 1.2123533
B34: DFR_DOE-2 | C34: {=SQRT(SUMPRODUCT((Heizlasten!G11:G5098/Heizlasten!G8-Heizlasten!J11:J5098/Heizlasten!J8)^2)/Heizlasten!G5)} -> 0.37268268 | D34: {=SQRT(SUMPRODUCT((Heizlasten!H11:H5098/Heizlasten!H8-Heizlasten!J11:J5098/Heizlasten!J8)^2)/Heizlasten!G5)} -> 0.38561681 | E34: {=SQRT(SUMPRODUCT((Heizlasten!I11:I5098/Heizlasten!I8-Heizlasten!J11:J5098/Heizlasten!J8)^2)/Heizlasten!G5)} -> 0.35481084 | F34: - | G34: {=SQRT(SUMPRODUCT((Heizlasten!J11:J5098/Heizlasten!J8-Heizlasten!K11:K5098/Heizlasten!K8)^2)/Heizlasten!G5)} -> 0.70412535 | I34: DFR_DOE-2 | J34: {=SQRT(SUMPRODUCT((Heizlasten!L11:L5098/Heizlasten!L8-Heizlasten!O11:O5098/Heizlasten!O8)^2)/Heizlasten!L5)} -> 0.36153338 | K34: {=SQRT(SUMPRODUCT((Heizlasten!M11:M5098/Heizlasten!M8-Heizlasten!O11:O5098/Heizlasten!O8)^2)/Heizlasten!L5)} -> 0.39501024 | L34: {=SQRT(SUMPRODUCT((Heizlasten!N11:N5098/Heizlasten!N8-Heizlasten!O11:O5098/Heizlasten!O8)^2)/Heizlasten!L5)} -> 0.36629695 | M34: - | N34: {=SQRT(SUMPRODUCT((Heizlasten!P11:P5098/Heizlasten!P8-Heizlasten!O11:O5098/Heizlasten!O8)^2)/Heizlasten!L5)} -> 1.0438274
B35: WSOA | C35: {=SQRT(SUMPRODUCT((Heizlasten!G11:G5098/Heizlasten!G8-Heizlasten!K11:K5098/Heizlasten!K8)^2)/Heizlasten!G5)} -> 0.76363433 | D35: {=SQRT(SUMPRODUCT((Heizlasten!H11:H5098/Heizlasten!H8-Heizlasten!K11:K5098/Heizlasten!K8)^2)/Heizlasten!G5)} -> 0.75103122 | E35: {=SQRT(SUMPRODUCT((Heizlasten!I11:I5098/Heizlasten!I8-Heizlasten!K11:K5098/Heizlasten!K8)^2)/Heizlasten!G5)} -> 0.77915689 | F35: {=SQRT(SUMPRODUCT((Heizlasten!J11:J5098/Heizlasten!J8-Heizlasten!K11:K5098/Heizlasten!K8)^2)/Heizlasten!G5)} -> 0.70412535 | G35: - | I35: WSOA | J35: {=SQRT(SUMPRODUCT((Heizlasten!L11:L5098/Heizlasten!L8-Heizlasten!P11:P5098/Heizlasten!P8)^2)/Heizlasten!L5)} -> 1.151047 | K35: {=SQRT(SUMPRODUCT((Heizlasten!P11:P5098/Heizlasten!P8-Heizlasten!M11:M5098/Heizlasten!M8)^2)/Heizlasten!L5)} -> 1.1387387 | L35: {=SQRT(SUMPRODUCT((Heizlasten!P11:P5098/Heizlasten!P8-Heizlasten!N11:N5098/Heizlasten!N8)^2)/Heizlasten!L5)} -> 1.2123533 | M35: {=SQRT(SUMPRODUCT((Heizlasten!P11:P5098/Heizlasten!P8-Heizlasten!O11:O5098/Heizlasten!O8)^2)/Heizlasten!L5)} -> 1.0438274 | N35: -

Sheet Heizlasten
A1: Heizlasten nach Modell
A2: Stunde | B2: Datum | C2: Uhrzeit | D2: T_aussen | E2: u | F2: Tor voll offen | G2: Orientierung S/N | L2: Orientierung O/W
G3: AFN_E+ | H3: DFR_BLAST | I3: DFR_DEFAULT | J3: DFR_DOE-2 | K3: WSOA | L3: AFN_E+ | M3: DFR_BLAST | N3: DFR_DEFAULT | O3: DFR_DOE-2 | P3: WSOA
D4: [°C] | E4: [m/s] | F4: [%] | G4: [kW] | H4: [kW] | I4: [kW] | J4: [kW] | K4: [kW] | L4: [kW] | M4: [kW] | N4: [kW] | O4: [kW] | P4: [kW]
E5: Anzahl Werte | F5: - | G5: =COUNT(G11:G5098) -> 5088 | H5: =COUNT(H11:H5098) -> 5088 | I5: =COUNT(I11:I5098) -> 5088 | J5: =COUNT(J11:J5098) -> 5088 | K5: =COUNT(K11:K5098) -> 5088 | L5: =COUNT(L11:L5098) -> 5088 | M5: =COUNT(M11:M5098) -> 5088 | N5: =COUNT(N11:N5098) -> 5088 | ... P5: =COUNT(P11:P5098) -> 5088
E6: Jahresbedarf | F6: [MWh] | G6: =SUM(G11:G5098)/1000 -> 80.467131 | H6: =SUM(H11:H5098)/1000 -> 91.350358 | I6: =SUM(I11:I5098)/1000 -> 77.076722 | J6: =SUM(J11:J5098)/1000 -> 67.406884 | K6: =SUM(K11:K5098)/1000 -> 85.708909 | L6: =SUM(L11:L5098)/1000 -> 81.356261 | M6: =SUM(M11:M5098)/1000 -> 93.709129 | N6: =SUM(N11:N5098)/1000 -> 78.691264 | ... P6: =SUM(P11:P5098)/1000 -> 109.09902
E7: Maximum | F7: [kW] | G7: =MAX(G11:G5098) -> 85.25724 | H7: =MAX(H11:H5098) -> 99.13346 | I7: =MAX(I11:I5098) -> 67.80807 | J7: =MAX(J11:J5098) -> 85.37004 | K7: =MAX(K11:K5098) -> 223.98191 | L7: =MAX(L11:L5098) -> 84.77213 | M7: =MAX(M11:M5098) -> 103.3449 | N7: =MAX(N11:N5098) -> 70.17827 | ... P7: =MAX(P11:P5098) -> 393.77763
E8: Mittelwert | F8: [kW] | G8: =AVERAGE(G11:G5098) -> 15.815081 | H8: =AVERAGE(H11:H5098) -> 17.95408 | I8: =AVERAGE(I11:I5098) -> 15.148727 | J8: =AVERAGE(J11:J5098) -> 13.248208 | K8: =AVERAGE(K11:K5098) -> 16.845304 | L8: =AVERAGE(L11:L5098) -> 15.989831 | M8: =AVERAGE(M11:M5098) -> 18.417675 | N8: =AVERAGE(N11:N5098) -> 15.46605 | ... P8: =AVERAGE(P11:P5098) -> 21.442418
E9: Standardabweichung | F9: [kW] | G9: =_xlfn.STDEV.P(G11:G5098) -> 11.102868 | H9: =_xlfn.STDEV.P(H11:H5098) -> 13.155175 | I9: =_xlfn.STDEV.P(I11:I5098) -> 9.761662 | J9: =_xlfn.STDEV.P(J11:J5098) -> 8.01994 | K9: =_xlfn.STDEV.P(K11:K5098) -> 16.193905 | L9: =_xlfn.STDEV.P(L11:L5098) -> 11.248832 | M9: =_xlfn.STDEV.P(M11:M5098) -> 13.654963 | N9: =_xlfn.STDEV.P(N11:N5098) -> 10.042866 | ... P9: =_xlfn.STDEV.P(P11:P5098) -> 28.025104
E10: Variationskoeffizienz | F10: - | G10: =G9/G8 -> 0.70204309 | H10: =H9/H8 -> 0.73271227 | I10: =I9/I8 -> 0.64438828 | J10: =J9/J8 -> 0.60536035 | K10: =K9/K8 -> 0.96133048 | L10: =L9/L8 -> 0.70349913 | M10: =M9/M8 -> 0.74140537 | N10: =N9/N8 -> 0.64934914 | ... P10: =P9/P8 -> 1.3069936
A11: 0 | B11: 01.01. | C11: 00:00 | D11: -8.036 | E11: 4.176 | F11: 0 | G11: 23.06994 | H11: 22.65767 | I11: 22.65767 | J11: 22.65767 | K11: 22.65767 | L11: 23.06363 | M11: 22.67185 | N11: 22.67185 | O11: 22.67185 | P11: 22.67185
A12: 1 | B12: 01.01. | C12: 01:00 | D12: -6.793 | E12: 4.887 | F12: 0 | G12: 22.46483 | H12: 22.2779 | I12: 22.2779 | J12: 22.2779 | K12: 22.2779 | L12: 23.06104 | M12: 22.29021 | N12: 22.29021 | O12: 22.29021 | P12: 22.29021
A13: 2 | B13: 01.01. | C13: 02:00 | D13: -6.146 | E13: 3.083 | F13: 0 | G13: 21.53045 | H13: 21.6482 | I13: 21.6482 | J13: 21.6482 | K13: 21.6482 | L13: 21.51451 | M13: 21.65896 | N13: 21.65896 | O13: 21.65896 | P13: 21.65896
A14: 3 | B14: 01.01. | C14: 03:00 | D14: -5.747 | E14: 2.608 | F14: 0 | G14: 21.10589 | H14: 21.21574 | I14: 21.21574 | J14: 21.21574 | K14: 21.21574 | L14: 20.87425 | M14: 21.22517 | N14: 21.22517 | O14: 21.22517 | P14: 21.22517
A15: 4 | B15: 01.01. | C15: 04:00 | D15: -5.549 | E15: 2.033 | F15: 0 | G15: 20.74299 | H15: 20.93944 | I15: 20.93944 | J15: 20.93944 | K15: 20.93944 | L15: 20.47221 | M15: 20.94768 | N15: 20.94768 | O15: 20.94768 | P15: 20.94768
A16: 5 | B16: 01.01. | C16: 05:00 | D16: -5.398 | E16: 1.254 | F16: 0 | G16: 20.53533 | H16: 20.73912 | I16: 20.73912 | J16: 20.73912 | K16: 20.73912 | L16: 20.13476 | M16: 20.74643 | N16: 20.74643 | O16: 20.74643 | P16: 20.74643
A17: 6 | B17: 01.01. | C17: 06:00 | D17: -5.249 | E17: 1.246 | F17: 0 | G17: 20.45154 | H17: 20.64394 | I17: 20.64394 | J17: 20.64394 | K17: 20.64394 | L17: 20.02692 | M17: 20.65042 | N17: 20.65042 | O17: 20.65042 | P17: 20.65042
A18: 7 | B18: 01.01. | C18: 07:00 | D18: -5.149 | E18: 1.813 | F18: 0 | G18: 11.00169 | H18: 11.1913 | I18: 11.1913 | J18: 11.1913 | K18: 11.1913 | L18: 10.6567 | M18: 11.19706 | N18: 11.19706 | O18: 11.19706 | P18: 11.19706
A19: 8 | B19: 01.01. | C19: 08:00 | D19: -5.1 | E19: 1.532 | F19: 0 | G19: 10.88869 | H19: 11.07731 | I19: 11.07731 | J19: 11.07731 | K19: 11.07731 | L19: 10.51143 | M19: 11.08248 | N19: 11.08248 | O19: 11.08248 | P19: 11.08248
A20: 9 | B20: 01.01. | C20: 09:00 | D20: -4.846 | E20: 1.567 | F20: 0 | G20: 10.67102 | H20: 10.87815 | I20: 10.87815 | J20: 10.87815 | K20: 10.87815 | L20: 10.31136 | M20: 10.8828 | N20: 10.8828 | O20: 10.8828 | P20: 10.8828
A21: 10 | B21: 01.01. | C21: 10:00 | D21: -4.447 | E21: 3.871 | F21: 0 | G21: 10.9704 | H21: 10.5704 | I21: 10.5704 | J21: 10.5704 | K21: 10.5704 | L21: 10.64438 | M21: 10.5746 | N21: 10.5746 | O21: 10.5746 | P21: 10.5746
A22: 11 | B22: 01.01. | C22: 11:00 | D22: -3.995 | E22: 3.829 | F22: 0 | G22: 10.13693 | H22: 10.09718 | I22: 10.09718 | J22: 10.09718 | K22: 10.09718 | L22: 10.20376 | M22: 10.10095 | N22: 10.10095 | O22: 10.10095 | P22: 10.10095
... A5098: 5087 | B5098: 31.12. | C5098: 23:00 | D5098: -8.642 | E5098: 1.805 | F5098: 31.67 | G5098: 63.22954 | H5098: 76.29448 | I5098: 53.65324 | J5098: 34.82309 | K5098: 23.03523 | L5098: 63.0232 | M5098: 79.43382 | N5098: 55.61295 | O5098: 35.80174 | P5098: 34.12752

Sheet Lastgradienten
F1: in kW
A2: Uebergang_Nr | B2: Stunde_von | C2: Stunde_nach | D2: Datum_nach | E2: Uhrzeit_nach | F2: AFN_E+_SN | G2: DFR_BLAST_SN | H2: DFR_DEFAULT_SN | I2: DFR_DOE-2_SN | J2: WSOA_SN | K2: AFN_E+_OW | L2: DFR_BLAST_OW | M2: DFR_DEFAULT_OW | N2: DFR_DOE-2_OW | O2: WSOA_OW
E3: MIN | F3: =MIN(F8:F5094) -> 0 | G3: =MIN(G8:G5094) -> 0 | H3: =MIN(H8:H5094) -> 0 | I3: =MIN(I8:I5094) -> 0 | J3: =MIN(J8:J5094) -> 0 | K3: =MIN(K8:K5094) -> 0 | L3: =MIN(L8:L5094) -> 0 | M3: =MIN(M8:M5094) -> 0 | ... O3: =MIN(O8:O5094) -> 0
E4: MAX | F4: =MAX(F8:F5094) -> 53.698 | G4: =MAX(G8:G5094) -> 61.711 | H4: =MAX(H8:H5094) -> 36.355 | I4: =MAX(I8:I5094) -> 65.499 | J4: =MAX(J8:J5094) -> 196.021 | K4: =MAX(K8:K5094) -> 70.605 | L4: =MAX(L8:L5094) -> 64.814 | M4: =MAX(M8:M5094) -> 38.244 | ... O4: =MAX(O8:O5094) -> 337.957
E5: Anzahl | F5: =COUNT(F8:F5094) -> 5087 | G5: =COUNT(G8:G5094) -> 5087 | H5: =COUNT(H8:H5094) -> 5087 | I5: =COUNT(I8:I5094) -> 5087 | J5: =COUNT(J8:J5094) -> 5087 | K5: =COUNT(K8:K5094) -> 5087 | L5: =COUNT(L8:L5094) -> 5087 | M5: =COUNT(M8:M5094) -> 5087 | ... O5: =COUNT(O8:O5094) -> 5087
E6: Mittelwert | F6: =AVERAGE(F8:F5094) -> 4.7739996 | G6: =AVERAGE(G8:G5094) -> 6.188734 | H6: =AVERAGE(H8:H5094) -> 4.1903853 | I6: =AVERAGE(I8:I5094) -> 2.9621989 | J6: =AVERAGE(J8:J5094) -> 6.705745 | K6: =AVERAGE(K8:K5094) -> 5.0261693 | L6: =AVERAGE(L8:L5094) -> 6.4849626 | M6: =AVERAGE(M8:M5094) -> 4.3769045 | ... O6: =AVERAGE(O8:O5094) -> 10.803712
E7: Median | F7: =MEDIAN(F8:F5094) -> 2.218 | G7: =MEDIAN(G8:G5094) -> 2.969 | H7: =MEDIAN(H8:H5094) -> 2.216 | I7: =MEDIAN(I8:I5094) -> 1.25 | J7: =MEDIAN(J8:J5094) -> 1.25 | K7: =MEDIAN(K8:K5094) -> 2.287 | L7: =MEDIAN(L8:L5094) -> 3.109 | M7: =MEDIAN(M8:M5094) -> 2.315 | ... O7: =MEDIAN(O8:O5094) -> 1.361
A8: 1 | B8: 1 | C8: 2 | D8: 01.01. | E8: 0.041666667 | F8: 0.605 | G8: 0.38 | H8: 0.38 | I8: 0.38 | J8: 0.38 | K8: 0.002 | L8: 0.382 | M8: 0.382 | N8: 0.382 | O8: 0.382
A9: 2 | B9: 2 | C9: 3 | D9: 01.01. | E9: 0.083333333 | F9: 0.934 | G9: 0.63 | H9: 0.63 | I9: 0.63 | J9: 0.63 | K9: 1.547 | L9: 0.631 | M9: 0.631 | N9: 0.631 | O9: 0.631
A10: 3 | B10: 3 | C10: 4 | D10: 01.01. | E10: 0.125 | F10: 0.424 | G10: 0.432 | H10: 0.432 | I10: 0.432 | J10: 0.432 | K10: 0.64 | L10: 0.434 | M10: 0.434 | N10: 0.434 | O10: 0.434
A11: 4 | B11: 4 | C11: 5 | D11: 01.01. | E11: 0.16666667 | F11: 0.363 | G11: 0.276 | H11: 0.276 | I11: 0.276 | J11: 0.276 | K11: 0.402 | L11: 0.277 | M11: 0.277 | N11: 0.277 | O11: 0.277
A12: 5 | B12: 5 | C12: 6 | D12: 01.01. | E12: 0.20833333 | F12: 0.208 | G12: 0.2 | H12: 0.2 | I12: 0.2 | J12: 0.2 | K12: 0.337 | L12: 0.201 | M12: 0.201 | N12: 0.201 | O12: 0.201
A13: 6 | B13: 6 | C13: 7 | D13: 01.01. | E13: 0.25 | F13: 0.084 | G13: 0.095 | H13: 0.095 | I13: 0.095 | J13: 0.095 | K13: 0.108 | L13: 0.096 | M13: 0.096 | N13: 0.096 | O13: 0.096
A14: 7 | B14: 7 | C14: 8 | D14: 01.01. | E14: 0.29166667 | F14: 9.45 | G14: 9.453 | H14: 9.453 | I14: 9.453 | J14: 9.453 | K14: 9.371 | L14: 9.453 | M14: 9.453 | N14: 9.453 | O14: 9.453
A15: 8 | B15: 8 | C15: 9 | D15: 01.01. | E15: 0.33333333 | F15: 0.113 | G15: 0.114 | H15: 0.114 | I15: 0.114 | J15: 0.114 | K15: 0.145 | L15: 0.115 | M15: 0.115 | N15: 0.115 | O15: 0.115
A16: 9 | B16: 9 | C16: 10 | D16: 01.01. | E16: 0.375 | F16: 0.217 | G16: 0.199 | H16: 0.199 | I16: 0.199 | J16: 0.199 | K16: 0.2 | L16: 0.2 | M16: 0.2 | N16: 0.2 | O16: 0.2
A17: 10 | B17: 10 | C17: 11 | D17: 01.01. | E17: 0.41666667 | F17: 0.299 | G17: 0.308 | H17: 0.308 | I17: 0.308 | J17: 0.308 | K17: 0.333 | L17: 0.308 | M17: 0.308 | N17: 0.308 | O17: 0.308
A18: 11 | B18: 11 | C18: 12 | D18: 01.01. | E18: 0.45833333 | F18: 0.833 | G18: 0.473 | H18: 0.473 | I18: 0.473 | J18: 0.473 | K18: 0.441 | L18: 0.474 | M18: 0.474 | N18: 0.474 | O18: 0.474
A19: 12 | B19: 12 | C19: 13 | D19: 01.01. | E19: 0.5 | F19: 0.695 | G19: 0.556 | H19: 0.556 | I19: 0.556 | J19: 0.556 | K19: 0.967 | L19: 0.555 | M19: 0.555 | N19: 0.555 | O19: 0.555
... A5094: 5087 | B5094: 5087 | C5094: 5088 | D5094: 31.12. | E5094: 0.95833333 | F5094: 9.763 | G5094: 11.483 | H5094: 6.832 | I5094: 0.012 | J5094: 0.123 | K5094: 9.82 | L5094: 12.129 | M5094: 7.235 | N5094: 0.06 | O5094: 0.076
