Workbook

Sheet Übersicht
B2: Zuordnung der Excel Seiten zum Kapitel 5
B4: Kapitel der Arbeit | D4: Excel Seite | E4: Inhalt
B5: 4.6.2 Isotherme Simulation: Anströmrandbedingungen | D5: 4.6.2 Wetter'!A1 | E5: Auswertung der Wetterdatei von EnergyPlus + Herleitung der Konstruierten Wetterdatei
B6: 5.1 Bestimmung der Winddruckbeiwerte
C7: 5.1.1 Normwerte nach DIN EN 16798-7 und DIN EN 1991-1-4 | D7: 5.1.1 DIN 16798'!A1 | E7: Herleitung der Werte aus DIN EN 16798-7
D8: 5.1.1 DIN 1991'!A1 | E8: Herleitung der Werte aus DIN EN 1991-1-4
C9: 5.1.2 SurfaceAverageCalculation | D9: 5.1 C_P'!A1 | E9: Berechnung der C_P-Wert aus E+ und CFD und C_P-Vergleich
C10: 5.1.3 CFD-Simulation | D10: 5.1 C_P'!A1
C11: 5.1.4 Ergebnisspanne der cp-Quellen | D11: 5.1 C_P'!A1
B12: 5.2 Analytische Handrechnung und EnergyPlus-Simulation
C13: 5.2.1 DesignFlowRate: BLAST- und DOE-2-Koeffizientensatz | D13: 5.2.1 DFR'!A1 | E13: Berechnung für ZoneVentilation:DesignFlowRate
C14: 5.2.2 WindandStackOpenArea | D14: 5.2.2 WSOA'!A1 | E14: Berechnung für ZoneVentilation:WindandStackOpenArea
C15: 5.2.3 AirflowNetwork | D15: 5.2.3 AFN_1Zone'!A1 | E15: Berechnung des AirflowNetworks
D16: 5.2.3 AFN_2Zonen'!A1
C17: 5.3.4 Befunde zur EnergyPlus-Dokumentation | D17: 5.2.4 C_W-Nachweis'!A1 | E17: Nachweis des Fehlers in der EngineeringReference
B18: 5.4 Ergebnisse der CFD-Simulation | D18: 5.3 CFD'!A1 | E18: Ergebnisse der CFD-Simulation
B19: 5.5 Ergebnisspannen im Luftwechsel | D19: 5.4 Ergebnis'!A1 | E19: Vergleich der Luftwechselraten der Modellen
B21: Abweichung der Handrechnung | D21: Sim vs. Hand'!A1 | E21: Abweichung zwischen der Handrechnung und der Simulation

Sheet 4.6.2 Wetter
E2: Country | G2: Suburbs
B3: Berechnung Windgeschwindigkeit | E3: Tor | F3: Zone | G3: Tor | H3: Zone
B4: v_wind,h | C4: Wetterdatei | D4: m/s | E4: 6.5 | F4: 6.5 | G4: 6.5 | H4: 6.5
B5: h_wind | C5: Höhe Wind | D5: m | E5: 10 | F5: 10 | G5: 10 | H5: 10
B6: h | C6: Bezugshöhe | D6: m | E6: 1.7 | F6: 6 | G6: 1.7 | H6: 6
B7: α | C7: Offenland-Standardwert | D7: - | E7: 0.14 | F7: 0.14 | G7: 0.22 | H7: 0.22
B8: δ | C8: Offenland-Standardwert | D8: m | E8: 270 | F8: 270 | G8: 370 | H8: 370
B9: v_wind (U) | C9: Windgeschwindigkeit auf Torhöhe | D9: m/s | E9: =E4*(E8/E5)^E7*(E6/E8)^E7 -> 5.0719645 | F9: =F4*(F8/F5)^F7*(F6/F8)^F7 -> 6.0513815 | G9: =G4*(G8/G5)^G7*(G6/G8)^G7 -> 4.4016157 | H9: =H4*(H8/H5)^H7*(H6/H8)^H7 -> 5.8090703
B28: Formel ASHRAE S. 24.3 (4)

Sheet 5.1.1 DIN 16798
B1: „Die angegebenen Winddruck-Koeffizienten gelten für einen Windvektor von etwa ± 60 ° zur Fassadenachse. Die Windrichtung wird nicht spezifischer betrachtet."
B3: Eigenschaft | C3: Begründung | D3: Quelle | F3: zugeordnete Werte nach Tabelle B.7
B4: offen | C4: vgl. mit künstlichem Windkanal der CFD | D4: Tabelle B.6 | F4: Luv | G4: C_p1 | H4: 0.5
B5: niedig | C5: Tor Höhe 3m < 15 m | D5: Tabelle B.7 | F5: Lee | G5: C_p2 | H5: -0.7
B7: Anmerkungen:
B8: - Bezugsgeschwindigkeit Gl. (4) und (2): Mit den Standardwerten aus B.3.4.2 (C_top = C_rgh;met = C_top;met = 1, C_rgh;site = C_rgh;10;site) und Tabelle B.13 (Offenes Gelände = 1,0) folgt u_site = u_10 = 6,5 m/s. Es gibt keine Höhenkorrektur auf die Öffnungshöhe
B9: - f_cros: Tabelle B.10 listet keine Industie- und Logistikgebäude.
B11: DIN EN 16798-7:2017 S. 55 - 56

Sheet 5.1.1 DIN 1991
B2: Zonenzuordnung nach Bild 7.5 | N2: Interpolation nach Bild 7.2
B3: Fälle | E3: 1 - 3 | F3: 4 - 6 | H3: Fall | I3: Tor | J3: Lage | K3: Zone | L3: C_pe,10 | N3: Zone | O3: A | P3: B | Q3: D | R3: E
B4: h | C4: Höhe | D4: m | E4: 12 | F4: 12 | H4: 1 | I4: Tor 2 | J4: 6 - 9 m | K4: B | L4: =P7 -> -0.81372725 | N4: Bereich | O4: 1 | P4: 1 | Q4: ≤ 0,25 | R4: ≤ 0,25
B5: b | C5: quer zum Wind | D5: m | E5: 60 | F5: 15 | I5: Tor 5 | J5: 6 - 9 m | K5: B | L5: =P7 -> -0.81372725 | N5: c_pe,1 | O5: -1.4 | P5: -1.1 | Q5: 1 | R5: -0.3
B6: d | C6: in Windrichtung | D6: m | E6: 15 | F6: 60 | H6: 2 | I6: Tor 2 | J6: 6 - 9 m | K6: B | L6: =P7 -> -0.81372725 | N6: c_pe,10 | O6: -1.2 | P6: -0.8 | Q6: 0.7 | R6: -0.3
B7: h/d | E7: =E4/E6 -> 0.8 | F7: =F4/F6 -> 0.2 | I7: Tor 5 | J7: 6 - 9 m | K7: B | L7: =P7 -> -0.81372725 | N7: c_pe,9 | O7: =O5-(O5-O6)*LOG10(9) -> -1.2091515 | P7: =P5-(P5-P6)*LOG10(9) -> -0.81372725 | Q7: =Q5-(Q5-Q6)*LOG10(9) -> 0.71372725 | R7: =R5-(R5-R6)*LOG10(9) -> -0.3
B8: e* [MIN(h; 2*b)] | D8: m | E8: =MIN(E5,2*E4) -> 24 | H8: 3 | I8: Tor 2 | J8: 6 - 9 m | K8: B | L8: =P7 -> -0.81372725
B9: Zone A | D9: m | E9: 0 - 4,8 | I9: Tor 4 | J9: 1 - 4 m | K9: A | L9: =O7 -> -1.2091515
B10: Zone B | D10: m | E10: 4,8 - 15 | H10: 4 | I10: Tor 2 | J10: Luv | K10: D | L10: =Q7 -> 0.71372725
B11: * → d ≤ e ≤ 5d → zwei Zonen A und B | I11: Tor 5 | J11: Lee | K11: E | L11: -0.3
H12: 5 | I12: Tor 2 | J12: Luv | K12: D | L12: =Q7 -> 0.71372725
I13: Tor 5 | J13: Lee | K13: E | L13: -0.3
H14: 6 | I14: Tor 2 | J14: Luv | K14: D | L14: =Q7 -> 0.71372725
I15: Tor 4 | J15: Lee | K15: E | L15: -0.3
B29: DIN EN 1991-1-4:2010-12 S. 36 - 38

Sheet 5.1 C_P
E2: ganze Fassade gemittelt | G2: horiz. Streifen gemittelt (z = 0 - 3 m) | I2: Torfläche (3 x 3 m) mit Abstand d von der Fassade | U2: Tor + 1 m Rand, minus Torloch | W2: vert. Streifen, Torbreite
C3: AFN | E3: A | G3: B | I3: C, d = 0,05 m | K3: C, d = 0,25 m | M3: C, d = 0,50 m | O3: C, d = 1,00 m | Q3: C, d = 2,00 m | S3: C, d = 4,00 m | U3: D | W3: E | Y3: DIN EN 16798-7 | AA3: DIN EN 1991-1-4
C4: Tor 2 | D4: Tor 4/5 | E4: Tor 2 | F4: Tor 4/5 | G4: Tor 2 | H4: Tor 4/5 | I4: Tor 2 | J4: Tor 4/5 | K4: Tor 2 | L4: Tor 4/5 | M4: Tor 2 | N4: Tor 4/5 | O4: Tor 2 | P4: Tor 4/5 | Q4: Tor 2 | R4: Tor 4/5 | S4: Tor 2 | T4: Tor 4/5 | U4: Tor 2 | V4: Tor 4/5 | W4: Tor 2 | X4: Tor 4/5 | Y4: To2 | Z4: Tor 4/5 | AA4: Tor 2 | AB4: Tor 4/5
B5: 1 | C5: ='5.2.3 AFN_1Zone'!E4 -> 0.0325 | D5: ='5.2.3 AFN_1Zone'!E5 -> -0.44 | E5: -0.549 | F5: -0.515 | G5: -0.429 | H5: -0.521 | I5: -0.26290201 | J5: -0.50658662 | K5: -0.26286818 | L5: -0.51399205 | M5: -0.25357826 | N5: -0.51359775 | O5: -0.25123518 | P5: -0.50969667 | Q5: -0.23783022 | R5: -0.49157547 | S5: -0.22977998 | T5: -0.47957305 | U5: -0.24315843 | V5: -0.52995597 | W5: -0.49121452 | X5: -0.51064083 | Y5: - | Z5: - | AA5: ='5.1.1 DIN 1991'!L4 -> -0.81372725 | AB5: ='5.1.1 DIN 1991'!L5 -> -0.81372725
B6: 2 | C6: ='5.2.3 AFN_1Zone'!E4 -> 0.0325 | D6: ='5.2.3 AFN_1Zone'!E5 -> -0.44 | E6: -0.552 | F6: -0.507 | G6: -0.427 | H6: -0.509 | I6: -0.23372458 | J6: -0.50380387 | K6: -0.2361804 | L6: -0.51292805 | M6: -0.23084258 | N6: -0.51493138 | O6: -0.23530067 | P6: -0.51768243 | Q6: -0.23114233 | R6: -0.51584587 | S6: -0.22742619 | T6: -0.49386799 | U6: -0.2387075 | V6: -0.52160551 | W6: -0.49017198 | X6: -0.5123774 | Y6: - | Z6: - | AA6: ='5.1.1 DIN 1991'!L8 -> -0.81372725 | AB6: ='5.1.1 DIN 1991'!L7 -> -0.81372725
B7: 3 | C7: ='5.2.3 AFN_1Zone'!E4 -> 0.0325 | D7: ='5.2.3 AFN_1Zone'!E5 -> -0.44 | E7: -0.546 | F7: -0.504 | G7: -0.424 | H7: -0.502 | I7: -0.24624179 | J7: -0.49519962 | K7: -0.24700427 | L7: -0.50749166 | M7: -0.23952307 | N7: -0.50592866 | O7: -0.23996621 | P7: -0.49721708 | Q7: -0.23058059 | R7: -0.48625529 | S7: -0.22414224 | T7: -0.50365407 | U7: -0.2391844 | V7: -0.5230989 | W7: -0.48807585 | X7: -0.50679704 | Y7: - | Z7: - | AA7: ='5.1.1 DIN 1991'!L6 -> -0.81372725 | AB7: ='5.1.1 DIN 1991'!L9 -> -1.2091515
B8: 4 | C8: ='5.2.3 AFN_1Zone'!J4 -> 0.48 | D8: ='5.2.3 AFN_1Zone'!J5 -> -0.315 | E8: 0.912 | F8: -0.34 | G8: 0.912 | H8: -0.333 | I8: 0.68679641 | J8: -0.23778528 | K8: 0.81771027 | L8: -0.24813158 | M8: 0.90297781 | N8: -0.32909567 | O8: 0.95811779 | P8: -0.39064244 | Q8: 0.92701076 | R8: -0.43096897 | S8: 0.78832068 | T8: -0.43385346 | U8: 1.0590345 | V8: -0.38361724 | W8: 0.89368298 | X8: -0.28164996 | Y8: ='5.1.1 DIN 16798'!H4 -> 0.5 | Z8: ='5.1.1 DIN 16798'!H$5 -> -0.7 | AA8: ='5.1.1 DIN 1991'!L10 -> 0.71372725 | AB8: ='5.1.1 DIN 1991'!L11 -> -0.3
B9: 5 | C9: ='5.2.3 AFN_1Zone'!J4 -> 0.48 | D9: ='5.2.3 AFN_1Zone'!J5 -> -0.315 | E9: 0.912 | F9: -0.359 | G9: 0.924 | H9: -0.307 | I9: 0.74518876 | J9: -0.21306815 | K9: 0.85714565 | L9: -0.22547623 | M9: 0.92898973 | N9: -0.30330113 | O9: 0.97236047 | P9: -0.36303808 | Q9: 0.93305097 | R9: -0.39138891 | S9: 0.79044251 | T9: -0.37765724 | U9: 1.0676863 | V9: -0.3657989 | W9: 0.90925243 | X9: -0.33471473 | Y9: ='5.1.1 DIN 16798'!H4 -> 0.5 | Z9: ='5.1.1 DIN 16798'!H$5 -> -0.7 | AA9: ='5.1.1 DIN 1991'!L12 -> 0.71372725 | AB9: ='5.1.1 DIN 1991'!L13 -> -0.3
B10: 6 | C10: ='5.2.3 AFN_1Zone'!J4 -> 0.48 | D10: ='5.2.3 AFN_1Zone'!J5 -> -0.315 | E10: 0.911 | F10: -0.336 | G10: 0.902 | H10: -0.28 | I10: 0.63958687 | J10: -0.25825561 | K10: 0.78561669 | L10: -0.2682682 | M10: 0.88130083 | N10: -0.31841152 | O10: 0.94607639 | P10: -0.33482962 | Q10: 0.92175638 | R10: -0.31692297 | S10: 0.7866504 | T10: -0.32224661 | U10: 1.0504676 | V10: -0.40710816 | W10: 0.88069799 | X10: -0.38118617 | Y10: ='5.1.1 DIN 16798'!H4 -> 0.5 | Z10: ='5.1.1 DIN 16798'!H$5 -> -0.7 | AA10: ='5.1.1 DIN 1991'!L14 -> 0.71372725 | AB10: ='5.1.1 DIN 1991'!L15 -> -0.3
B11: Δ C_p = C_p,Süd - C_p,Nord
B12: 1 | C12: =C5-D5 -> 0.4725 | E12: =E5-F5 -> -0.034 | G12: =G5-H5 -> 0.092 | I12: =I5-J5 -> 0.24368461 | K12: =K5-L5 -> 0.25112387 | M12: =M5-N5 -> 0.26001949 | O12: =O5-P5 -> 0.25846148 | Q12: =Q5-R5 -> 0.25374525 | S12: =S5-T5 -> 0.24979307 | U12: =U5-V5 -> 0.28679754 | W12: =W5-X5 -> 0.019426314 | Y12: - | AA12: =AA5-AB5 -> 0
B13: 2 | C13: =C6-D6 -> 0.4725 | E13: =E6-F6 -> -0.045 | G13: =G6-H6 -> 0.082 | I13: =I6-J6 -> 0.2700793 | K13: =K6-L6 -> 0.27674765 | M13: =M6-N6 -> 0.28408879 | O13: =O6-P6 -> 0.28238176 | Q13: =Q6-R6 -> 0.28470354 | S13: =S6-T6 -> 0.2664418 | U13: =U6-V6 -> 0.28289801 | W13: =W6-X6 -> 0.022205417 | Y13: - | AA13: =AA6-AB6 -> 0
B14: 3 | C14: =C7-D7 -> 0.4725 | E14: =E7-F7 -> -0.042 | G14: =G7-H7 -> 0.078 | I14: =I7-J7 -> 0.24895783 | K14: =K7-L7 -> 0.2604874 | M14: =M7-N7 -> 0.26640559 | O14: =O7-P7 -> 0.25725087 | Q14: =Q7-R7 -> 0.2556747 | S14: =S7-T7 -> 0.27951183 | U14: =U7-V7 -> 0.2839145 | W14: =W7-X7 -> 0.018721184 | Y14: - | AA14: =AA7-AB7 -> 0.39542425
B15: 4 | C15: =C8-D8 -> 0.795 | E15: =E8-F8 -> 1.252 | G15: =G8-H8 -> 1.245 | I15: =I8-J8 -> 0.92458169 | K15: =K8-L8 -> 1.0658418 | M15: =M8-N8 -> 1.2320735 | O15: =O8-P8 -> 1.3487602 | Q15: =Q8-R8 -> 1.3579797 | S15: =S8-T8 -> 1.2221741 | U15: =U8-V8 -> 1.4426518 | W15: =W8-X8 -> 1.1753329 | Y15: =Y8-Z8 -> 1.2 | AA15: =AA8-AB8 -> 1.0137272
B16: 5 | C16: =C9-D9 -> 0.795 | E16: =E9-F9 -> 1.271 | G16: =G9-H9 -> 1.231 | I16: =I9-J9 -> 0.9582569 | K16: =K9-L9 -> 1.0826219 | M16: =M9-N9 -> 1.2322909 | O16: =O9-P9 -> 1.3353985 | Q16: =Q9-R9 -> 1.3244399 | S16: =S9-T9 -> 1.1680998 | U16: =U9-V9 -> 1.4334852 | W16: =W9-X9 -> 1.2439672 | Y16: =Y9-Z9 -> 1.2 | AA16: =AA9-AB9 -> 1.0137272
B17: 6 | C17: =C10-D10 -> 0.795 | E17: =E10-F10 -> 1.247 | G17: =G10-H10 -> 1.182 | I17: =I10-J10 -> 0.89784247 | K17: =K10-L10 -> 1.0538849 | M17: =M10-N10 -> 1.1997124 | O17: =O10-P10 -> 1.280906 | Q17: =Q10-R10 -> 1.2386793 | S17: =S10-T10 -> 1.108897 | U17: =U10-V10 -> 1.4575757 | W17: =W10-X10 -> 1.2618842 | Y17: =Y10-Z10 -> 1.2 | AA17: =AA10-AB10 -> 1.0137272
B18: ACH
B19: 1 | C19: =$H$44*$H$50*$H$45*SQRT(C12)*3600/$H$48 -> 4.610723 | E19: - | G19: =$H$44*$H$50*$H$45*SQRT(G12)*3600/$H$48 -> 2.0345203 | I19: =$H$44*$H$50*$H$45*SQRT(I12)*3600/$H$48 -> 3.3111753 | K19: =$H$44*$H$50*$H$45*SQRT(K12)*3600/$H$48 -> 3.3613375 | M19: =$H$44*$H$50*$H$45*SQRT(M12)*3600/$H$48 -> 3.4203541 | O19: =$H$44*$H$50*$H$45*SQRT(O12)*3600/$H$48 -> 3.4100915 | Q19: =$H$44*$H$50*$H$45*SQRT(Q12)*3600/$H$48 -> 3.3788358 | S19: =$H$44*$H$50*$H$45*SQRT(S12)*3600/$H$48 -> 3.3524192 | U19: =$H$44*$H$50*$H$45*SQRT(U12)*3600/$H$48 -> 3.5921613 | W19: =$H$44*$H$50*$H$45*SQRT(W12)*3600/$H$48 -> 0.93489606
B20: 2 | C20: =$H$44*$H$51*$H$45*SQRT(C13)*3600/$H$48 -> 4.5103566 | E20: - | G20: =$H$44*$H$51*$H$45*SQRT(G13)*3600/$H$48 -> 1.8789573 | I20: =$H$44*$H$51*$H$45*SQRT(I13)*3600/$H$48 -> 3.4100098 | K20: =$H$44*$H$51*$H$45*SQRT(K13)*3600/$H$48 -> 3.4518502 | M20: =$H$44*$H$51*$H$45*SQRT(M13)*3600/$H$48 -> 3.4973333 | O20: =$H$44*$H$51*$H$45*SQRT(O13)*3600/$H$48 -> 3.4868101 | Q20: =$H$44*$H$51*$H$45*SQRT(Q13)*3600/$H$48 -> 3.5011153 | S20: =$H$44*$H$51*$H$45*SQRT(S13)*3600/$H$48 -> 3.3869685 | U20: =$H$44*$H$51*$H$45*SQRT(U13)*3600/$H$48 -> 3.489996 | W20: =$H$44*$H$51*$H$45*SQRT(W13)*3600/$H$48 -> 0.97777616
B21: 3 | C21: =$H$44*$H$50*$H$45*SQRT(C14)*3600/$H$48 -> 4.610723 | E21: - | G21: =$H$44*$H$50*$H$45*SQRT(G14)*3600/$H$48 -> 1.8733349 | I21: =$H$44*$H$50*$H$45*SQRT(I14)*3600/$H$48 -> 3.3468097 | K21: =$H$44*$H$50*$H$45*SQRT(K14)*3600/$H$48 -> 3.4234302 | M21: =$H$44*$H$50*$H$45*SQRT(M14)*3600/$H$48 -> 3.4621014 | O21: =$H$44*$H$50*$H$45*SQRT(O14)*3600/$H$48 -> 3.4020959 | Q21: =$H$44*$H$50*$H$45*SQRT(Q14)*3600/$H$48 -> 3.3916576 | S21: =$H$44*$H$50*$H$45*SQRT(S14)*3600/$H$48 -> 3.5462408 | U21: =$H$44*$H$50*$H$45*SQRT(U14)*3600/$H$48 -> 3.5740606 | W21: =$H$44*$H$50*$H$45*SQRT(W14)*3600/$H$48 -> 0.91777195
B22: 4 | C22: =$H$44*$H$50*$H$45*SQRT(C15)*3600/$H$48 -> 5.9806954 | E22: =$H$44*$H$50*$H$45*SQRT(E15)*3600/$H$48 -> 7.5053385 | G22: =$H$44*$H$50*$H$45*SQRT(G15)*3600/$H$48 -> 7.4843278 | I22: =$H$44*$H$50*$H$45*SQRT(I15)*3600/$H$48 -> 6.4497186 | K22: =$H$44*$H$50*$H$45*SQRT(K15)*3600/$H$48 -> 6.9249159 | M22: =$H$44*$H$50*$H$45*SQRT(M15)*3600/$H$48 -> 7.4453724 | O22: =$H$44*$H$50*$H$45*SQRT(O15)*3600/$H$48 -> 7.7899649 | Q22: =$H$44*$H$50*$H$45*SQRT(Q15)*3600/$H$48 -> 7.8165438 | S22: =$H$44*$H$50*$H$45*SQRT(S15)*3600/$H$48 -> 7.4154014 | U22: =$H$44*$H$50*$H$45*SQRT(U15)*3600/$H$48 -> 8.0565457 | W22: =$H$44*$H$50*$H$45*SQRT(W15)*3600/$H$48 -> 7.2719113
B23: 5 | C23: =$H$44*$H$51*$H$45*SQRT(C16)*3600/$H$48 -> 5.8505075 | E23: =$H$44*$H$51*$H$45*SQRT(E16)*3600/$H$48 -> 7.3974622 | G23: =$H$44*$H$51*$H$45*SQRT(G16)*3600/$H$48 -> 7.2801278 | I23: =$H$44*$H$51*$H$45*SQRT(I16)*3600/$H$48 -> 6.4231928 | K23: =$H$44*$H$51*$H$45*SQRT(K16)*3600/$H$48 -> 6.8272904 | M23: =$H$44*$H$51*$H$45*SQRT(M16)*3600/$H$48 -> 7.2839439 | O23: =$H$44*$H$51*$H$45*SQRT(O16)*3600/$H$48 -> 7.5825525 | Q23: =$H$44*$H$51*$H$45*SQRT(Q16)*3600/$H$48 -> 7.5513761 | S23: =$H$44*$H$51*$H$45*SQRT(S16)*3600/$H$48 -> 7.0916933 | U23: =$H$44*$H$51*$H$45*SQRT(U16)*3600/$H$48 -> 7.8560925 | W23: =$H$44*$H$51*$H$45*SQRT(W16)*3600/$H$48 -> 7.3183712
B24: 6 | C24: =$H$44*$H$50*$H$45*SQRT(C17)*3600/$H$48 -> 5.9806954 | E24: =$H$44*$H$50*$H$45*SQRT(E17)*3600/$H$48 -> 7.4903369 | G24: =$H$44*$H$50*$H$45*SQRT(G17)*3600/$H$48 -> 7.2925071 | I24: =$H$44*$H$50*$H$45*SQRT(I17)*3600/$H$48 -> 6.3557703 | K24: =$H$44*$H$50*$H$45*SQRT(K17)*3600/$H$48 -> 6.8859634 | M24: =$H$44*$H$50*$H$45*SQRT(M17)*3600/$H$48 -> 7.3469433 | O24: =$H$44*$H$50*$H$45*SQRT(O17)*3600/$H$48 -> 7.5914853 | Q24: =$H$44*$H$50*$H$45*SQRT(Q17)*3600/$H$48 -> 7.4653053 | S24: =$H$44*$H$50*$H$45*SQRT(S17)*3600/$H$48 -> 7.0633988 | U24: =$H$44*$H$50*$H$45*SQRT(U17)*3600/$H$48 -> 8.0981103 | W24: =$H$44*$H$50*$H$45*SQRT(W17)*3600/$H$48 -> 7.5349065
B25: Volumenstrom Q [m³/s]
B26: 1 | E26: ='5.3 CFD'!$J5 -> 9.807 | G26: ='5.3 CFD'!$J5 -> 9.807 | I26: ='5.3 CFD'!$J5 -> 9.807 | K26: ='5.3 CFD'!$J5 -> 9.807 | M26: ='5.3 CFD'!$J5 -> 9.807 | O26: ='5.3 CFD'!$J5 -> 9.807 | Q26: ='5.3 CFD'!$J5 -> 9.807 | S26: ='5.3 CFD'!$J5 -> 9.807 | U26: ='5.3 CFD'!$J5 -> 9.807 | W26: ='5.3 CFD'!$J5 -> 9.807
B27: 2 | E27: ='5.3 CFD'!$J6 -> 8.5715 | G27: ='5.3 CFD'!$J6 -> 8.5715 | I27: ='5.3 CFD'!$J6 -> 8.5715 | K27: ='5.3 CFD'!$J6 -> 8.5715 | M27: ='5.3 CFD'!$J6 -> 8.5715 | O27: ='5.3 CFD'!$J6 -> 8.5715 | Q27: ='5.3 CFD'!$J6 -> 8.5715 | S27: ='5.3 CFD'!$J6 -> 8.5715 | U27: ='5.3 CFD'!$J6 -> 8.5715 | W27: ='5.3 CFD'!$J6 -> 8.5715
B28: 3 | E28: ='5.3 CFD'!$J7 -> 9.159 | G28: ='5.3 CFD'!$J7 -> 9.159 | I28: ='5.3 CFD'!$J7 -> 9.159 | K28: ='5.3 CFD'!$J7 -> 9.159 | M28: ='5.3 CFD'!$J7 -> 9.159 | O28: ='5.3 CFD'!$J7 -> 9.159 | Q28: ='5.3 CFD'!$J7 -> 9.159 | S28: ='5.3 CFD'!$J7 -> 9.159 | U28: ='5.3 CFD'!$J7 -> 9.159 | W28: ='5.3 CFD'!$J7 -> 9.159
B29: 4 | E29: ='5.3 CFD'!$J8 -> 24.08 | G29: ='5.3 CFD'!$J8 -> 24.08 | I29: ='5.3 CFD'!$J8 -> 24.08 | K29: ='5.3 CFD'!$J8 -> 24.08 | M29: ='5.3 CFD'!$J8 -> 24.08 | O29: ='5.3 CFD'!$J8 -> 24.08 | Q29: ='5.3 CFD'!$J8 -> 24.08 | S29: ='5.3 CFD'!$J8 -> 24.08 | U29: ='5.3 CFD'!$J8 -> 24.08 | W29: ='5.3 CFD'!$J8 -> 24.08
B30: 5 | E30: ='5.3 CFD'!$J9 -> 22.269 | G30: ='5.3 CFD'!$J9 -> 22.269 | I30: ='5.3 CFD'!$J9 -> 22.269 | K30: ='5.3 CFD'!$J9 -> 22.269 | M30: ='5.3 CFD'!$J9 -> 22.269 | O30: ='5.3 CFD'!$J9 -> 22.269 | Q30: ='5.3 CFD'!$J9 -> 22.269 | S30: ='5.3 CFD'!$J9 -> 22.269 | U30: ='5.3 CFD'!$J9 -> 22.269 | W30: ='5.3 CFD'!$J9 -> 22.269
B31: 6 | E31: ='5.3 CFD'!$J10 -> 25.1645 | G31: ='5.3 CFD'!$J10 -> 25.1645 | I31: ='5.3 CFD'!$J10 -> 25.1645 | K31: ='5.3 CFD'!$J10 -> 25.1645 | M31: ='5.3 CFD'!$J10 -> 25.1645 | O31: ='5.3 CFD'!$J10 -> 25.1645 | Q31: ='5.3 CFD'!$J10 -> 25.1645 | S31: ='5.3 CFD'!$J10 -> 25.1645 | U31: ='5.3 CFD'!$J10 -> 25.1645 | W31: ='5.3 CFD'!$J10 -> 25.1645
B32: Effektiver C_D = Q_CFD/(A_eff. * U * √ΔC_p)
B33: 1 | E33: - | G33: =G26/($H$50*$H$45*SQRT(G12)) -> 0.9961955 | I33: =I26/($H$50*$H$45*SQRT(I12)) -> 0.6121029 | K33: =K26/($H$50*$H$45*SQRT(K12)) -> 0.60296832 | M33: =M26/($H$50*$H$45*SQRT(M12)) -> 0.59256438 | O33: =O26/($H$50*$H$45*SQRT(O12)) -> 0.59434768 | Q33: =Q26/($H$50*$H$45*SQRT(Q12)) -> 0.59984567 | S33: =S26/($H$50*$H$45*SQRT(S12)) -> 0.60457237 | U33: =U26/($H$50*$H$45*SQRT(U12)) -> 0.56422299 | W33: =W26/($H$50*$H$45*SQRT(W12)) -> 2.1679201
B34: 2 | E34: - | G34: =G27/($H$51*$H$45*SQRT(G13)) -> 0.94278 | I34: =I27/($H$51*$H$45*SQRT(I13)) -> 0.51948336 | K34: =K27/($H$51*$H$45*SQRT(K13)) -> 0.51318661 | M34: =M27/($H$51*$H$45*SQRT(M13)) -> 0.50651258 | O34: =O27/($H$51*$H$45*SQRT(O13)) -> 0.50804124 | Q34: =Q27/($H$51*$H$45*SQRT(Q13)) -> 0.50596544 | S34: =S27/($H$51*$H$45*SQRT(S13)) -> 0.52301736 | U34: =U27/($H$51*$H$45*SQRT(U13)) -> 0.50757747 | W34: =W27/($H$51*$H$45*SQRT(W13)) -> 1.8117064
B35: 3 | E35: - | G35: =G28/($H$50*$H$45*SQRT(G14)) -> 1.0104226 | I35: =I28/($H$50*$H$45*SQRT(I14)) -> 0.56557145 | K35: =K28/($H$50*$H$45*SQRT(K14)) -> 0.55291327 | M35: =M28/($H$50*$H$45*SQRT(M14)) -> 0.5467373 | O35: =O28/($H$50*$H$45*SQRT(O14)) -> 0.55638056 | Q35: =Q28/($H$50*$H$45*SQRT(Q14)) -> 0.5580929 | S35: =S28/($H$50*$H$45*SQRT(S14)) -> 0.53376522 | U35: =U28/($H$50*$H$45*SQRT(U14)) -> 0.52961049 | W35: =W28/($H$50*$H$45*SQRT(W14)) -> 2.0624514
B36: 4 | E36: =E29/($H$50*$H$45*SQRT(E15)) -> 0.6630658 | G36: =G29/($H$50*$H$45*SQRT(G15)) -> 0.66492723 | I36: =I29/($H$50*$H$45*SQRT(I15)) -> 0.77158922 | K36: =K29/($H$50*$H$45*SQRT(K15)) -> 0.71864169 | M36: =M29/($H$50*$H$45*SQRT(M15)) -> 0.66840623 | O36: =O29/($H$50*$H$45*SQRT(O15)) -> 0.638839 | Q36: =Q29/($H$50*$H$45*SQRT(Q15)) -> 0.63666672 | S36: =S29/($H$50*$H$45*SQRT(S15)) -> 0.67110774 | U36: =U29/($H$50*$H$45*SQRT(U15)) -> 0.61770062 | W36: =W29/($H$50*$H$45*SQRT(W15)) -> 0.68435011
B37: 5 | E37: =E30/($H$51*$H$45*SQRT(E16)) -> 0.62214039 | G37: =G30/($H$51*$H$45*SQRT(G16)) -> 0.63216747 | I37: =I30/($H$51*$H$45*SQRT(I16)) -> 0.7165066 | K37: =K30/($H$51*$H$45*SQRT(K16)) -> 0.67409759 | M37: =M30/($H$51*$H$45*SQRT(M16)) -> 0.63183628 | O37: =O30/($H$51*$H$45*SQRT(O16)) -> 0.60695392 | Q37: =Q30/($H$51*$H$45*SQRT(Q16)) -> 0.60945977 | S37: =S30/($H$51*$H$45*SQRT(S16)) -> 0.6489649 | U37: =U30/($H$51*$H$45*SQRT(U16)) -> 0.5858205 | W37: =W30/($H$51*$H$45*SQRT(W16)) -> 0.62886397
B38: 6 | E38: =E31/($H$50*$H$45*SQRT(E17)) -> 0.69431635 | G38: =G31/($H$50*$H$45*SQRT(G17)) -> 0.71315163 | I38: =I31/($H$50*$H$45*SQRT(I17)) -> 0.81825854 | K38: =K31/($H$50*$H$45*SQRT(K17)) -> 0.75525573 | M38: =M31/($H$50*$H$45*SQRT(M17)) -> 0.70786763 | O38: =O31/($H$50*$H$45*SQRT(O17)) -> 0.68506532 | Q38: =Q31/($H$50*$H$45*SQRT(Q17)) -> 0.69664443 | S38: =S31/($H$50*$H$45*SQRT(S17)) -> 0.7362834 | U38: =U31/($H$50*$H$45*SQRT(U17)) -> 0.64220703 | W38: =W31/($H$50*$H$45*SQRT(W17)) -> 0.69020941
E44: C_D | F44: Durchflusskoeffizient | G44: – | H44: 0.62
E45: U | F45: Bezugsgeschwindigkeit der C_p | G45: m/s | H45: 5.1
E46: A | F46: Toroeffnungsflaeche | G46: m² | H46: 9
...

Sheet 5.2.1 DFR
F2: Default | J2: BLAST | N2: DOE-2
F3: 0° | H3: 90 ° | J3: 0° | L3: 90 ° | N3: 0° | P3: 90 °
D4: Quelle | E4: Einheit | F4: 1/3 | G4: 2 | H4: 4/6 | I4: 5 | J4: 1/3 | K4: 2 | L4: 4/6 | M4: 5 | N4: 1/3 | O4: 2 | P4: 4/6 | Q4: 5
B5: C_D | C5: Durchflusskoeffizient | E5: - | F5: 0.62 | G5: 0.62 | H5: 0.62 | I5: 0.62 | J5: 0.62 | K5: 0.62 | L5: 0.62 | M5: 0.62 | N5: 0.62 | O5: 0.62 | P5: 0.62 | Q5: 0.62
B6: A_Tor | C6: Toröffnungsfläche | D6: Geometrie | E6: m² | F6: 9 | G6: 9 | H6: 9 | I6: 9 | J6: 9 | K6: 9 | L6: 9 | M6: 9 | N6: 9 | O6: 9 | P6: 9 | Q6: 9
B7: A_Spalt | C7: Spaltfläche | D7: Geometrie | E7: m² | G7: 30 | I7: 30 | K7: 30 | M7: 30 | O7: 30 | Q7: 30
B8: A_eff | C8: Toröffnungsfläche | E8: m² | F8: =1/(SQRT(1/F6^2+1/F6^2)) -> 6.363961 | G8: =1/(SQRT(1/G6^2+1/G7^2+1/G6^2)) -> 6.2254302 | H8: =1/(SQRT(1/H6^2+1/H6^2)) -> 6.363961 | I8: =1/(SQRT(1/I6^2+1/I7^2+1/I6^2)) -> 6.2254302 | J8: =1/(SQRT(1/J6^2+1/J6^2)) -> 6.363961 | K8: =1/(SQRT(1/K6^2+1/K7^2+1/K6^2)) -> 6.2254302 | L8: =1/(SQRT(1/L6^2+1/L6^2)) -> 6.363961 | M8: =1/(SQRT(1/M6^2+1/M7^2+1/M6^2)) -> 6.2254302 | N8: =1/(SQRT(1/N6^2+1/N6^2)) -> 6.363961 | O8: =1/(SQRT(1/O6^2+1/O7^2+1/O6^2)) -> 6.2254302 | P8: =1/(SQRT(1/P6^2+1/P6^2)) -> 6.363961 | Q8: =1/(SQRT(1/Q6^2+1/Q7^2+1/Q6^2)) -> 6.2254302
B9: ϑ | C9: Anströmwinkel an die Fassadennormale | E9: ° | F9: 67.5 | G9: 67.5 | H9: 22.5 | I9: 22.5 | J9: 67.5 | K9: 67.5 | L9: 22.5 | M9: 22.5 | N9: 67.5 | O9: 67.5 | P9: 22.5 | Q9: 22.5
B10: v_wind (Tor) | C10: Windgeschwindigkeit | D10: Wetterdatei | E10: m/s | F10: ='4.6.2 Wetter'!$E$9 -> 5.0719645 | G10: ='4.6.2 Wetter'!$E$9 -> 5.0719645 | H10: ='4.6.2 Wetter'!$E$9 -> 5.0719645 | I10: ='4.6.2 Wetter'!$E$9 -> 5.0719645 | J10: ='4.6.2 Wetter'!$E$9 -> 5.0719645 | K10: ='4.6.2 Wetter'!$E$9 -> 5.0719645 | L10: ='4.6.2 Wetter'!$E$9 -> 5.0719645 | M10: ='4.6.2 Wetter'!$E$9 -> 5.0719645 | ... Q10: ='4.6.2 Wetter'!$E$9 -> 5.0719645
B11: T_zone | C11: Innentemperatur | D11: ASR A3.5 | E11: °C | F11: 17 | G11: 17 | H11: 17 | I11: 17 | J11: 17 | K11: 17 | L11: 17 | M11: 17 | N11: 17 | O11: 17 | P11: 17 | Q11: 17
B12: T_odb | C12: Außentemperatur | D12: Annahme | E12: °C | F12: 17 | G12: 17 | H12: 17 | I12: 17 | J12: 17 | K12: 17 | L12: 17 | M12: 17 | N12: 17 | O12: 17 | P12: 17 | Q12: 17
B13: ΔT | E13: K | F13: =F11-F12 -> 0 | G13: =G11-G12 -> 0 | H13: =H11-H12 -> 0 | I13: =I11-I12 -> 0 | J13: =J11-J12 -> 0 | K13: =K11-K12 -> 0 | L13: =L11-L12 -> 0 | M13: =M11-M12 -> 0 | ... Q13: =Q11-Q12 -> 0
B14: F_Schedule | C14: Zeitplanwert | D14: Schedule | E14: - | F14: 1 | G14: 1 | H14: 1 | I14: 1 | J14: 1 | K14: 1 | L14: 1 | M14: 1 | N14: 1 | O14: 1 | P14: 1 | Q14: 1
B15: Normierungspunkt der Koeffizienten | F15: - | G15: - | H15: - | I15: - | J15: BLAST | K15: BLAST | L15: BLAST | M15: BLAST | N15: DOE-2 | O15: DOE-2 | P15: DOE-2 | Q15: DOE-2
B16: A | C16: Constant Term Coefficient | E16: - | F16: 1 | G16: 1 | H16: 1 | I16: 1 | J16: 0.606 | K16: 0.606 | L16: 0.606 | M16: 0.606 | N16: 0 | O16: 0 | P16: 0 | Q16: 0
B17: B | C17: Temperature Term Coefficient | E17: 1/K | F17: 0 | G17: 0 | H17: 0 | I17: 0 | J17: 0.03636 | K17: 0.03636 | L17: 0.03636 | M17: 0.03636 | N17: 0 | O17: 0 | P17: 0 | Q17: 0
B18: C | C18: Velocity Term Coefficient | E18: s/m | F18: 0 | G18: 0 | H18: 0 | I18: 0 | J18: 0.1177 | K18: 0.1177 | L18: 0.1177 | M18: 0.1177 | N18: 0.224 | O18: 0.224 | P18: 0.224 | Q18: 0.224
B19: D | C19: Velocity Squared Term Coefficient | E19: s²/m² | F19: 0 | G19: 0 | H19: 0 | I19: 0 | J19: 0 | K19: 0 | L19: 0 | M19: 0 | N19: 0 | O19: 0 | P19: 0 | Q19: 0
B20: u_ref | C20: Normierungsgeschwindigkeit | D20: Eng.Ref | E20: m/s | F20: - | G20: - | H20: - | I20: - | J20: 3.347493 | K20: 3.347493 | L20: 3.347493 | M20: 3.347493 | N20: =1/N18 -> 4.4642857 | O20: =1/O18 -> 4.4642857 | P20: =1/P18 -> 4.4642857 | Q20: =1/Q18 -> 4.4642857
B21: V_design | C21: Auslegungs-Volumenstrom | D21: = C_D * A * cosϑ * u_ref | E21: m³/s | F21: =F5*F8*F10*COS(RADIANS(F9)) -> 7.6583475 | G21: =G5*G8*G10*COS(RADIANS(G9)) -> 7.4916404 | H21: =H5*H8*H10*COS(RADIANS(H9)) -> 18.488886 | I21: =I5*I8*I10*COS(RADIANS(I9)) -> 18.08642 | J21: =F21 -> 7.6583475 | K21: =G21 -> 7.4916404 | L21: =H21 -> 18.488886 | M21: =I21 -> 18.08642 | N21: =F21 -> 7.6583475 | O21: =G21 -> 7.4916404 | P21: =H21 -> 18.488886 | Q21: =I21 -> 18.08642
B22: Q_vent | E22: m³/s | F22: =F21*(F16+F17*F13+F18*F10) -> 7.6583475 | G22: =G21*(G16+G17*G13+G18*G10) -> 7.4916404 | H22: =H21*(H16+H17*H13+H18*H10) -> 18.488886 | I22: =I21*(I16+I17*I13+I18*I10) -> 18.08642 | J22: =J21*(J16+J17*J13+J18*J10) -> 9.212764 | K22: =K21*(K16+K17*K13+K18*K10) -> 9.0122203 | L22: =L21*(L16+L17*L13+L18*L10) -> 22.24158 | M22: =M21*(M16+M17*M13+M18*M10) -> 21.757424 | ... Q22: =Q21*(Q16+Q17*Q13+Q18*Q10) -> 20.548344
B23: ACH | C23: Luftwechsel | E23: 1/h | F23: =F22*3600/10800 -> 2.5527825 | G23: =G22*3600/10800 -> 2.4972135 | H23: =H22*3600/10800 -> 6.1629621 | I23: =I22*3600/10800 -> 6.0288066 | J23: =J22*3600/10800 -> 3.0709213 | K23: =K22*3600/10800 -> 3.0040734 | L23: =L22*3600/10800 -> 7.4138599 | M23: =M22*3600/10800 -> 7.2524748 | ... Q23: =Q22*3600/10800 -> 6.8494481
B24: k | C24: Vorfaktor, nur Torgeometrie | D24: = C_D * A * cosϑ | E24: m² | F24: =F5*F8*COS(RADIANS(F9)) -> 1.5099371 | G24: =G5*G8*COS(RADIANS(G9)) -> 1.4770688 | H24: =H5*H8*COS(RADIANS(H9)) -> 3.6453107 | I24: =I5*I8*COS(RADIANS(I9)) -> 3.5659595 | J24: =J5*J8*COS(RADIANS(J9)) -> 1.5099371 | K24: =K5*K8*COS(RADIANS(K9)) -> 1.4770688 | L24: =L5*L8*COS(RADIANS(L9)) -> 3.6453107 | M24: =M5*M8*COS(RADIANS(M9)) -> 3.5659595 | ... Q24: =Q5*Q8*COS(RADIANS(Q9)) -> 3.5659595
B25: Q_soll | D25: = k * v_wind (tor) | E25: m³/s | F25: =F10*F24 -> 7.6583475 | G25: =G10*G24 -> 7.4916404 | H25: =H10*H24 -> 18.488886 | I25: =I10*I24 -> 18.08642 | J25: =J10*J24 -> 7.6583475 | K25: =K10*K24 -> 7.4916404 | L25: =L10*L24 -> 18.488886 | M25: =M10*M24 -> 18.08642 | ... Q25: =Q10*Q24 -> 18.08642
B26: Abweichung von Q_soll | F26: =(F22-F25)/F25 -> 0 | G26: =(G22-G25)/G25 -> 0 | H26: =(H22-H25)/H25 -> 1.9215401e-16 | I26: =(I22-I25)/I25 -> 0 | J26: =(J22-J25)/J25 -> 0.20297022 | K26: =(K22-K25)/K25 -> 0.20297022 | L26: =(L22-L25)/L25 -> 0.20297022 | M26: =(M22-M25)/M25 -> 0.20297022 | ... Q26: =(Q22-Q25)/Q25 -> 0.13612005
B27: Q_design ohne cos | F27: =F5*F8*F10 -> 20.012226 | G27: =G5*G8*G10 -> 19.5766 | H27: =H5*H8*H10 -> 20.012226 | I27: =I5*I8*I10 -> 19.5766 | J27: =J5*J8*J10 -> 20.012226 | K27: =K5*K8*K10 -> 19.5766 | L27: =L5*L8*L10 -> 20.012226 | M27: =M5*M8*M10 -> 19.5766 | ... Q27: =Q5*Q8*Q10 -> 19.5766
B28: Q_vent ohne cos | F28: =F27*(F16+F17*F13+F18*F10) -> 20.012226 | G28: =G27*(G16+G17*G13+G18*G10) -> 19.5766 | H28: =H27*(H16+H17*H13+H18*H10) -> 20.012226 | I28: =I27*(I16+I17*I13+I18*I10) -> 19.5766 | J28: =J27*(J16+J17*J13+J18*J10) -> 24.074112 | K28: =K27*(K16+K17*K13+K18*K10) -> 23.550067 | L28: =L27*(L16+L17*L13+L18*L10) -> 24.074112 | M28: =M27*(M16+M17*M13+M18*M10) -> 23.550067 | ... Q28: =Q27*(Q16+Q17*Q13+Q18*Q10) -> 22.241367
B34: EngRef: Gleichung 8.5 (452) Verweis auf Kap. 26 ASHRAE

Sheet 5.2.2 WSOA
F2: 1/2/3 | H2: 4/5/6 | K2: *² wird in EnergyPlus automatisch für jeden Zeitschritt über Windrichtung berechnet [autocalculate]
B3: Symbol | C3: Bedeutung | D3: Quelle | E3: Einheit | F3: Tor 2 | G3: Tor 4/5 | H3: Tor 2 | I3: Tor 4/5 | K3: *³ ΔH_NPL ist die Höhe von der Mitte der unteren Öffnung zur neutralen Druckzone. Deine Tore 2 und 5 sitzen auf gleicher Höhe (Sturz 0, Oberkante 3 m, Mitte 1,5 m). Bei zwei gleich hohen Öffnungen liegt die neutrale Ebene auf Toröffnungsmitte → ΔH_NPL = 0 → Qs = 0. -> WindandStackOpenArea bildet für symmetrische Tor-gegen-Tor-Geometrie den Auftrieb nicht ab.
B4: EffectiveAngle | E4: ° | F4: 180 | G4: 0 | H4: 180 | I4: 0
B5: WindDirection | E5: ° | F5: 247.5 | G5: 247.5 | H5: 157.5 | I5: 157.5
B6: delta | F6: =ABS(F4-F5) -> 67.5 | G6: =ABS(G4-G5) -> 247.5 | H6: =ABS(H4-H5) -> 22.5 | I6: =ABS(I4-I5) -> 157.5
B7: C_W/C_v*² | C7: Opening Effectiveness (windabhängig) | D7: autocal. | E7: - | F7: =MAX(0,0.55-(F6/45)*0.25) -> 0.175 | G7: =MAX(0,0.55-(G6/45)*0.25) -> 0 | H7: =MAX(0,0.55-(H6/45)*0.25) -> 0.425 | I7: =MAX(0,0.55-(I6/45)*0.25) -> 0
B8: A | C8: Öffnungsfläche | E8: m² | F8: 9 | G8: 9 | H8: 9 | I8: 9
B9: F_Schedule | C9: Öffnungsanteil | D9: Schedule | E9: - | F9: 1 | G9: 1 | H9: 1 | I9: 1
B10: v_wind Torhöhe | C10: Windgeschwindigkeit | D10: Wetterdatei | E10: m/s | F10: ='4.6.2 Wetter'!$E$9 -> 5.0719645 | G10: ='4.6.2 Wetter'!$E$9 -> 5.0719645 | H10: ='4.6.2 Wetter'!$E$9 -> 5.0719645 | I10: ='4.6.2 Wetter'!$E$9 -> 5.0719645
B11: v_wind Zonenschwerpunkt | C11: Windgeschwindigkeit | D11: Wetterdatei | E11: m/s | F11: ='4.6.2 Wetter'!$F$9 -> 6.0513815 | G11: ='4.6.2 Wetter'!$F$9 -> 6.0513815 | H11: ='4.6.2 Wetter'!$F$9 -> 6.0513815 | I11: ='4.6.2 Wetter'!$F$9 -> 6.0513815
B12: C_D | C12: Discharge Coefficient (Stack) | D12: autocal. | E12: -
B13: g | C13: Erdbeschleunigung | E13: m/s²
B14: Δh_NPL*³ | C14: Höhe Öffnungsmitte -> neutrale Ebene | E14: m
B15: T_zone | C15: Innentemperatur | D15: ASR A3.5 | E15: °C
B16: T_odb | C16: Außentemperatur | D16: Annahme | E16: °C
B17: Q_w | C17: Windanteil | E17: m³/s | F17: =F7*F8*F9*F10 -> 7.9883441 | G17: =G7*G8*G9*G10 -> 0 | H17: =H7*H8*H9*H10 -> 19.400264 | I17: =I7*I8*I9*I10 -> 0
B18: Q_s | C18: Thermikanteil | E18: m³/s
B19: Q_vent (V_total) | E19: m³/s | F19: =SQRT(F17*F17+F18*F18) -> 7.9883441 | G19: =SQRT(G17*G17+G18*G18) -> 0 | H19: =SQRT(H17*H17+H18*H18) -> 19.400264 | I19: =SQRT(I17*I17+I18*I18) -> 0
B20: Q_vent,gesamt | E20: m³/s | F20: =F19+G19 -> 7.9883441 | H20: =H19+I19 -> 19.400264
B21: ACH | F21: =F20/10800*3600 -> 2.6627814 | H21: =H20/10800*3600 -> 6.4667547 | K21: Quelle: Engineering Reference, ASHRAE Gleichung 37
K22: EngRef: Gleichungen 8.6 (453), 8.8 (454), 8.10 (454)
K23: 37 | L23: Wind only
K24: 38 | L24: Thermal Force only

Sheet 5.2.3 AFN_1Zone
E2: AFN_E+ | F2: AFN_CFD_D | G2: AFN_CFD_C1,00 | H2: AFN_CFD_D | I2: AFN_CFD_C1,00 | J2: AFN_E+ | K2: AFN_CFD_D | L2: AFN_CFD_C1,00 | M2: AFN_CFD_D | N2: AFN_CFD_C1,00 | W2: AFN_DIN_1 | Y2: AFN_DIN_2
B3: Eingabewerte | E3: 1/3 | F3: 1 | G3: 1 | H3: 3 | I3: 3 | J3: 4/6 | K3: 4 | L3: 4 | M3: 6 | N3: 6 | W3: 4 | X3: 6 | Y3: 1 | Z3: 3 | AA3: 4 | AB3: 6
B4: C_p,2 | C4: Winddruckkoeff. Luv (Tor 2) | D4: - | E4: 0.0325 | F4: ='5.1 C_P'!U5 -> -0.24315843 | G4: ='5.1 C_P'!O5 -> -0.25123518 | H4: ='5.1 C_P'!U7 -> -0.2391844 | I4: ='5.1 C_P'!O7 -> -0.23996621 | J4: 0.48 | K4: ='5.1 C_P'!U8 -> 1.0590345 | L4: ='5.1 C_P'!O8 -> 0.95811779 | M4: ='5.1 C_P'!U10 -> 1.0504676 | N4: ='5.1 C_P'!O10 -> 0.94607639 | W4: 0.5 | X4: 0.5 | Y4: -0.8 | Z4: -0.8 | AA4: 0.7 | AB4: 0.7
B5: C_p,5 | C5: Winddruckkoeff. Lee (Tor 5) | D5: - | E5: -0.44 | F5: ='5.1 C_P'!V5 -> -0.52995597 | G5: ='5.1 C_P'!P5 -> -0.50969667 | H5: ='5.1 C_P'!V7 -> -0.5230989 | I5: ='5.1 C_P'!P7 -> -0.49721708 | J5: -0.315 | K5: ='5.1 C_P'!V8 -> -0.38361724 | L5: ='5.1 C_P'!P8 -> -0.39064244 | M5: ='5.1 C_P'!V10 -> -0.40710816 | N5: ='5.1 C_P'!P10 -> -0.33482962 | W5: -0.7 | X5: -0.7 | Y5: -0.8 | Z5: -1.2 | AA5: -0.3 | AB5: -0.3
B6: t_außen | D6: °C | E6: 17 | F6: 17 | G6: 17 | H6: 17 | I6: 17 | J6: 17 | K6: 17 | L6: 17 | M6: 17 | N6: 17 | W6: 17 | X6: 17 | Y6: 17 | Z6: 17 | AA6: 17 | AB6: 17
B7: t_innen | D7: °C | E7: 17 | F7: 17 | G7: 17 | H7: 17 | I7: 17 | J7: 17 | K7: 17 | L7: 17 | M7: 17 | N7: 17 | W7: 17 | X7: 17 | Y7: 17 | Z7: 17 | AA7: 17 | AB7: 17
B8: Konstanten
B9: C_D | C9: Durchflusskoeffizient | D9: - | E9: 0.62 | F9: 0.62 | G9: 0.62 | H9: 0.62 | I9: 0.62 | J9: 0.62 | K9: 0.62 | L9: 0.62 | M9: 0.62 | N9: 0.62 | W9: 0.62 | X9: 0.62 | Y9: 0.62 | Z9: 0.62 | AA9: 0.62 | AB9: 0.62
B10: b_tor | C10: Breite Tor | D10: m | E10: 3 | F10: 3 | G10: 3 | H10: 3 | I10: 3 | J10: 3 | K10: 3 | L10: 3 | M10: 3 | N10: 3 | W10: 3 | X10: 3 | Y10: 3 | Z10: 3 | AA10: 3 | AB10: 3
B11: h_tor | C11: Höhe Tor | D11: m | E11: 3 | F11: 3 | G11: 3 | H11: 3 | I11: 3 | J11: 3 | K11: 3 | L11: 3 | M11: 3 | N11: 3 | W11: 3 | X11: 3 | Y11: 3 | Z11: 3 | AA11: 3 | AB11: 3
B12: A | C12: Öffnungsfläche pro Tor | D12: m² | E12: =E10*E11 -> 9 | F12: =F10*F11 -> 9 | G12: =G10*G11 -> 9 | H12: =H10*H11 -> 9 | I12: =I10*I11 -> 9 | J12: =J10*J11 -> 9 | K12: =K10*K11 -> 9 | L12: =L10*L11 -> 9 | ... N12: =N10*N11 -> 9 | W12: =W10*W11 -> 9 | X12: =X10*X11 -> 9 | Y12: =Y10*Y11 -> 9 | Z12: =Z10*Z11 -> 9 | AA12: =AA10*AA11 -> 9 | AB12: =AB10*AB11 -> 9
B13: g | C13: Erdbeschleunigung | D13: m/s² | E13: 9.81 | F13: 9.81 | G13: 9.81 | H13: 9.81 | I13: 9.81 | J13: 9.81 | K13: 9.81 | L13: 9.81 | M13: 9.81 | N13: 9.81 | W13: 9.81 | X13: 9.81 | Y13: 9.81 | Z13: 9.81 | AA13: 9.81 | AB13: 9.81
B14: p | C14: Stationsdruck | D14: Pa | E14: 95300 | F14: 95300 | G14: 95300 | H14: 95300 | I14: 95300 | J14: 95300 | K14: 95300 | L14: 95300 | M14: 95300 | N14: 95300 | W14: 95300 | X14: 95300 | Y14: 95300 | Z14: 95300 | AA14: 95300 | AB14: 95300
B15: R | C15: spez. Gaskonstante | D15: J/kgK | E15: 287.06 | F15: 287.06 | G15: 287.06 | H15: 287.06 | I15: 287.06 | J15: 287.06 | K15: 287.06 | L15: 287.06 | M15: 287.06 | N15: 287.06 | W15: 287.06 | X15: 287.06 | Y15: 287.06 | Z15: 287.06 | AA15: 287.06 | AB15: 287.06
B16: v_wind (U) | C16: Windgeschwindigkeit auf Torhöhe | D16: m/s | E16: ='4.6.2 Wetter'!$E$9 -> 5.0719645 | F16: ='4.6.2 Wetter'!$E$9 -> 5.0719645 | G16: ='4.6.2 Wetter'!$E$9 -> 5.0719645 | H16: ='4.6.2 Wetter'!$E$9 -> 5.0719645 | I16: ='4.6.2 Wetter'!$E$9 -> 5.0719645 | J16: ='4.6.2 Wetter'!$E$9 -> 5.0719645 | K16: ='4.6.2 Wetter'!$E$9 -> 5.0719645 | L16: ='4.6.2 Wetter'!$E$9 -> 5.0719645 | ... N16: ='4.6.2 Wetter'!$E$9 -> 5.0719645 | W16: ='4.6.2 Wetter'!$E$9 -> 5.0719645 | X16: ='4.6.2 Wetter'!$E$9 -> 5.0719645 | Y16: ='4.6.2 Wetter'!$E$9 -> 5.0719645 | Z16: ='4.6.2 Wetter'!$E$9 -> 5.0719645 | AA16: ='4.6.2 Wetter'!$E$9 -> 5.0719645 | AB16: ='4.6.2 Wetter'!$E$9 -> 5.0719645
B17: T_a, odb | C17: absolute Temperatur außen | D17: K | E17: =E6+273.15 -> 290.15 | F17: =F6+273.15 -> 290.15 | G17: =G6+273.15 -> 290.15 | H17: =H6+273.15 -> 290.15 | I17: =I6+273.15 -> 290.15 | J17: =J6+273.15 -> 290.15 | K17: =K6+273.15 -> 290.15 | L17: =L6+273.15 -> 290.15 | ... N17: =N6+273.15 -> 290.15 | W17: =W6+273.15 -> 290.15 | X17: =X6+273.15 -> 290.15 | Y17: =Y6+273.15 -> 290.15 | Z17: =Z6+273.15 -> 290.15 | AA17: =AA6+273.15 -> 290.15 | AB17: =AB6+273.15 -> 290.15
B18: T_i | C18: absolute Temperatur innen | D18: K | E18: =E7+273.15 -> 290.15 | F18: =F7+273.15 -> 290.15 | G18: =G7+273.15 -> 290.15 | H18: =H7+273.15 -> 290.15 | I18: =I7+273.15 -> 290.15 | J18: =J7+273.15 -> 290.15 | K18: =K7+273.15 -> 290.15 | L18: =L7+273.15 -> 290.15 | ... N18: =N7+273.15 -> 290.15 | W18: =W7+273.15 -> 290.15 | X18: =X7+273.15 -> 290.15 | Y18: =Y7+273.15 -> 290.15 | Z18: =Z7+273.15 -> 290.15 | AA18: =AA7+273.15 -> 290.15 | AB18: =AB7+273.15 -> 290.15
B19: ρ_a | C19: Luftdichte außen | D19: kg/m³ | E19: 1.13319 | F19: 1.13319 | G19: 1.13319 | H19: 1.13319 | I19: 1.13319 | J19: 1.13319 | K19: 1.13319 | L19: 1.13319 | M19: 1.13319 | N19: 1.13319 | W19: 1.13319 | X19: 1.13319 | Y19: 1.13319 | Z19: 1.13319 | AA19: 1.13319 | AB19: 1.13319
B20: ρ_i | C20: Luftdichte innen | D20: kg/m³ | E20: 1.13319 | F20: 1.13319 | G20: 1.13319 | H20: 1.13319 | I20: 1.13319 | J20: 1.13319 | K20: 1.13319 | L20: 1.13319 | M20: 1.13319 | N20: 1.13319 | W20: 1.13319 | X20: 1.13319 | Y20: 1.13319 | Z20: 1.13319 | AA20: 1.13319 | AB20: 1.13319
B21: b | C21: = (ρ_i - ρ_a) * g | D21: Pa/m | E21: =(E20-E19)*E13 -> 0 | F21: =(F20-F19)*F13 -> 0 | G21: =(G20-G19)*G13 -> 0 | H21: =(H20-H19)*H13 -> 0 | I21: =(I20-I19)*I13 -> 0 | J21: =(J20-J19)*J13 -> 0 | K21: =(K20-K19)*K13 -> 0 | L21: =(L20-L19)*L13 -> 0 | ... N21: =(N20-N19)*N13 -> 0 | W21: =(W20-W19)*W13 -> 0 | X21: =(X20-X19)*X13 -> 0 | Y21: =(Y20-Y19)*Y13 -> 0 | Z21: =(Z20-Z19)*Z13 -> 0 | AA21: =(AA20-AA19)*AA13 -> 0 | AB21: =(AB20-AB19)*AB13 -> 0
B22: p_w,2 | C22: Winddruck außen an Tor 2 | D22: Pa | E22: =E4*0.5*E19*E16^2 -> 0.47370559 | F22: =F4*0.5*F19*F16^2 -> -3.5441695 | G22: =G4*0.5*G19*G16^2 -> -3.6618927 | H22: =H4*0.5*H19*H16^2 -> -3.4862457 | I22: =I4*0.5*I19*I16^2 -> -3.4976411 | J22: =J4*0.5*J19*J16^2 -> 6.9962672 | K22: =K4*0.5*K19*K16^2 -> 15.436018 | L22: =L4*0.5*L19*L16^2 -> 13.9651 | ... N22: =N4*0.5*N19*N16^2 -> 13.78959 | W22: =W4*0.5*W19*W16^2 -> 7.2877783 | X22: =X4*0.5*X19*X16^2 -> 7.2877783 | Y22: =Y4*0.5*Y19*Y16^2 -> -11.660445 | Z22: =Z4*0.5*Z19*Z16^2 -> -11.660445 | AA22: =AA4*0.5*AA19*AA16^2 -> 10.20289 | AB22: =AB4*0.5*AB19*AB16^2 -> 10.20289
B23: p_w,5 | C23: Winddruck außen an Tor 5 | D23: Pa | E23: =E5*0.5*E19*E16^2 -> -6.4132449 | F23: =F5*0.5*F19*F16^2 -> -7.7244032 | G23: =G5*0.5*G19*G16^2 -> -7.4291126 | H23: =H5*0.5*H19*H16^2 -> -7.6244576 | I23: =I5*0.5*I19*I16^2 -> -7.2472157 | J23: =J5*0.5*J19*J16^2 -> -4.5913003 | K23: =K5*0.5*K19*K16^2 -> -5.5914349 | L23: =L5*0.5*L19*L16^2 -> -5.693831 | ... N23: =N5*0.5*N19*N16^2 -> -4.8803281 | W23: =W5*0.5*W19*W16^2 -> -10.20289 | X23: =X5*0.5*X19*X16^2 -> -10.20289 | Y23: =Y5*0.5*Y19*Y16^2 -> -11.660445 | Z23: =Z5*0.5*Z19*Z16^2 -> -17.490668 | AA23: =AA5*0.5*AA19*AA16^2 -> -4.372667 | AB23: =AB5*0.5*AB19*AB16^2 -> -4.372667
B24: AFN - Vereinfacht: iso
B25: Q_wind | D25: m³/s | E25: =E9*E12*E16*SQRT(0.5*(ABS(E4-E5))) -> 13.756131 | F25: =F9*F12*F16*SQRT(0.5*(ABS(F4-F5))) -> 10.717244 | G25: =G9*G12*G16*SQRT(0.5*(ABS(G4-G5))) -> 10.174037 | H25: =H9*H12*H16*SQRT(0.5*(ABS(H4-H5))) -> 10.66324 | I25: =I9*I12*I16*SQRT(0.5*(ABS(I4-I5))) -> 10.150182 | J25: =J9*J12*J16*SQRT(0.5*(ABS(J4-J5))) -> 17.843456 | K25: =K9*K12*K16*SQRT(0.5*(ABS(K4-K5))) -> 24.036773 | L25: =L9*L12*L16*SQRT(0.5*(ABS(L4-L5))) -> 23.241427 | ... N25: =N9*N12*N16*SQRT(0.5*(ABS(N4-N5))) -> 22.649261 | W25: =W9*W12*W16*SQRT(0.5*(ABS(W4-W5))) -> 21.922296 | X25: =X9*X12*X16*SQRT(0.5*(ABS(X4-X5))) -> 21.922296 | Y25: =Y9*Y12*Y16*SQRT(0.5*(ABS(Y4-Y5))) -> 0 | Z25: =Z9*Z12*Z16*SQRT(0.5*(ABS(Z4-Z5))) -> 12.656843 | AA25: =AA9*AA12*AA16*SQRT(0.5*(ABS(AA4-AA5))) -> 20.012226 | AB25: =AB9*AB12*AB16*SQRT(0.5*(ABS(AB4-AB5))) -> 20.012226
B26: Q_ein | D26: m³/s | E26: =E35+E41 -> 13.75613 | F26: =F35+F41 -> 10.717244 | G26: =G35+G41 -> 10.174037 | H26: =H35+H41 -> 10.66324 | I26: =I35+I41 -> 10.150182 | J26: =J35+J41 -> 17.843456 | K26: =K35+K41 -> 24.036773 | L26: =L35+L41 -> 23.241427 | ... N26: =N35+N41 -> 22.649261
B27: Q_aus | D27: m³/s | E27: =E36+E42 -> 13.756132 | F27: =F36+F42 -> 10.717244 | G27: =G36+G42 -> 10.174038 | H27: =H36+H42 -> 10.663241 | I27: =I36+I42 -> 10.150183 | J27: =J36+J42 -> 17.843456 | K27: =K36+K42 -> 24.036773 | L27: =L36+L42 -> 23.241427 | ... N27: =N36+N42 -> 22.649261
B28: Q_mittel | D28: m³/s | E28: =(E26+E27)/2 -> 13.756131 | F28: =(F26+F27)/2 -> 10.717244 | G28: =(G26+G27)/2 -> 10.174037 | H28: =(H26+H27)/2 -> 10.66324 | I28: =(I26+I27)/2 -> 10.150182 | J28: =(J26+J27)/2 -> 17.843456 | K28: =(K26+K27)/2 -> 24.036773 | L28: =(L26+L27)/2 -> 23.241427 | ... N28: =(N26+N27)/2 -> 22.649261
B29: ACH | C29: V = 10 800 m³ | D29: 1/h | E29: =E28*3600/10800 -> 4.5853771 | F29: =F28*3600/10800 -> 3.5724147 | G29: =G28*3600/10800 -> 3.3913457 | H29: =H28*3600/10800 -> 3.5544134 | I29: =I28*3600/10800 -> 3.383394 | J29: =J28*3600/10800 -> 5.9478186 | K29: =K28*3600/10800 -> 8.0122577 | L29: =L28*3600/10800 -> 7.7471422 | ... N29: =N28*3600/10800 -> 7.5497537 | P29: Methode: Knoten-Drucknetzwerk
B30: Zielwertsuche | P30: Jede Öffnung verbindet zwei Knoten. Druckdifferenz über die Torhöhe z: ΔP(z) = a + b·z
B31: p_z | C31: Druck Zone innen | D31: Pa | E31: -2.9697692 | F31: -5.6342862 | G31: -5.5455024 | H31: -5.5553515 | I31: -5.3724282 | J31: 1.2024833 | K31: 4.9222913 | L31: 4.1356346 | M31: 4.6886608 | N31: 4.4546309 | P31: a = p_w − P_z (Wind P_W + Knotendruck P_n−P_m, mit P_n=0 außen, P_m=P_z Zone)
B32: a_2 | C32: = p_w,2 - p_z | D32: Pa | E32: =E22-E31 -> 3.4434748 | F32: =F22-F31 -> 2.0901167 | G32: =G22-G31 -> 1.8836098 | H32: =H22-H31 -> 2.0691058 | I32: =I22-I31 -> 1.8747871 | J32: =J22-J31 -> 5.7937839 | K32: =K22-K31 -> 10.513726 | L32: =L22-L31 -> 9.8294656 | ... N32: =N22-N31 -> 9.3349591 | P32: b = (ρ_innen − ρ_außen)·g (Stack/Auftrieb P_S; isotherm = 0)
B33: ΔP_unten,2 | C33: z = 0 | D33: Pa | E33: =E32 -> 3.4434748 | F33: =F32 -> 2.0901167 | G33: =G32 -> 1.8836098 | H33: =H32 -> 2.0691058 | I33: =I32 -> 1.8747871 | J33: =J32 -> 5.7937839 | K33: =K32 -> 10.513726 | L33: =L32 -> 9.8294656 | ... N33: =N32 -> 9.3349591 | P33: p_w = Cp · ½ · ρ_außen · U² (Winddruck, Außendichte)
B34: ΔP_oben,2 | C34: z = h_tor | D34: Pa | E34: =E32+E21*E11 -> 3.4434748 | F34: =F32+F21*F11 -> 2.0901167 | G34: =G32+G21*G11 -> 1.8836098 | H34: =H32+H21*H11 -> 2.0691058 | I34: =I32+I21*I11 -> 1.8747871 | J34: =J32+J21*J11 -> 5.7937839 | K34: =K32+K21*K11 -> 10.513726 | L34: =L32+L21*L11 -> 9.8294656 | ... N34: =N32+N21*N11 -> 9.3349591
B35: Q_ein,2 | D35: m³/s | E35: =IF(ABS(E21)<0.000001,IF(E32>0,E9*E12*SQRT(2*E32/E19),0),E9*E10*SQRT(2/E19)*(2/(3*ABS(E21)))*ABS(MAX(E33,0)^1.5-MAX(E34,0)^1.5)) -> 13.75613 | F35: =IF(ABS(F21)<0.000001,IF(F32>0,F9*F12*SQRT(2*F32/F19),0),F9*F10*SQRT(2/F19)*(2/(3*ABS(F21)))*ABS(MAX(F33,0)^1.5-MAX(F34,0)^1.5)) -> 10.717244 | G35: =IF(ABS(G21)<0.000001,IF(G32>0,G9*G12*SQRT(2*G32/G19),0),G9*G10*SQRT(2/G19)*(2/(3*ABS(G21)))*ABS(MAX(G33,0)^1.5-MAX(G34,0)^1.5)) -> 10.174037 | H35: =IF(ABS(H21)<0.000001,IF(H32>0,H9*H12*SQRT(2*H32/H19),0),H9*H10*SQRT(2/H19)*(2/(3*ABS(H21)))*ABS(MAX(H33,0)^1.5-MAX(H34,0)^1.5)) -> 10.66324 | I35: =IF(ABS(I21)<0.000001,IF(I32>0,I9*I12*SQRT(2*I32/I19),0),I9*I10*SQRT(2/I19)*(2/(3*ABS(I21)))*ABS(MAX(I33,0)^1.5-MAX(I34,0)^1.5)) -> 10.150182 | J35: =IF(ABS(J21)<0.000001,IF(J32>0,J9*J12*SQRT(2*J32/J19),0),J9*J10*SQRT(2/J19)*(2/(3*ABS(J21)))*ABS(MAX(J33,0)^1.5-MAX(J34,0)^1.5)) -> 17.843456 | K35: =IF(ABS(K21)<0.000001,IF(K32>0,K9*K12*SQRT(2*K32/K19),0),K9*K10*SQRT(2/K19)*(2/(3*ABS(K21)))*ABS(MAX(K33,0)^1.5-MAX(K34,0)^1.5)) -> 24.036773 | L35: =IF(ABS(L21)<0.000001,IF(L32>0,L9*L12*SQRT(2*L32/L19),0),L9*L10*SQRT(2/L19)*(2/(3*ABS(L21)))*ABS(MAX(L33,0)^1.5-MAX(L34,0)^1.5)) -> 23.241427 | ... N35: =IF(ABS(N21)<0.000001,IF(N32>0,N9*N12*SQRT(2*N32/N19),0),N9*N10*SQRT(2/N19)*(2/(3*ABS(N21)))*ABS(MAX(N33,0)^1.5-MAX(N34,0)^1.5)) -> 22.649261 | P35: Zuordnung zu den AFN-Gleichungen (Engineering Reference)
B36: Q_aus,2 | D36: m³/s | E36: =IF(ABS(E21)<0.000001,IF(E32<0,E9*E12*SQRT(2*(-E32)/E19),0),E9*E10*SQRT(2/E19)*(2/(3*ABS(E21)))*ABS(MAX(-E33,0)^1.5-MAX(-E34,0)^1.5)) -> 0 | F36: =IF(ABS(F21)<0.000001,IF(F32<0,F9*F12*SQRT(2*(-F32)/F19),0),F9*F10*SQRT(2/F19)*(2/(3*ABS(F21)))*ABS(MAX(-F33,0)^1.5-MAX(-F34,0)^1.5)) -> 0 | G36: =IF(ABS(G21)<0.000001,IF(G32<0,G9*G12*SQRT(2*(-G32)/G19),0),G9*G10*SQRT(2/G19)*(2/(3*ABS(G21)))*ABS(MAX(-G33,0)^1.5-MAX(-G34,0)^1.5)) -> 0 | H36: =IF(ABS(H21)<0.000001,IF(H32<0,H9*H12*SQRT(2*(-H32)/H19),0),H9*H10*SQRT(2/H19)*(2/(3*ABS(H21)))*ABS(MAX(-H33,0)^1.5-MAX(-H34,0)^1.5)) -> 0 | I36: =IF(ABS(I21)<0.000001,IF(I32<0,I9*I12*SQRT(2*(-I32)/I19),0),I9*I10*SQRT(2/I19)*(2/(3*ABS(I21)))*ABS(MAX(-I33,0)^1.5-MAX(-I34,0)^1.5)) -> 0 | J36: =IF(ABS(J21)<0.000001,IF(J32<0,J9*J12*SQRT(2*(-J32)/J19),0),J9*J10*SQRT(2/J19)*(2/(3*ABS(J21)))*ABS(MAX(-J33,0)^1.5-MAX(-J34,0)^1.5)) -> 0 | K36: =IF(ABS(K21)<0.000001,IF(K32<0,K9*K12*SQRT(2*(-K32)/K19),0),K9*K10*SQRT(2/K19)*(2/(3*ABS(K21)))*ABS(MAX(-K33,0)^1.5-MAX(-K34,0)^1.5)) -> 0 | L36: =IF(ABS(L21)<0.000001,IF(L32<0,L9*L12*SQRT(2*(-L32)/L19),0),L9*L10*SQRT(2/L19)*(2/(3*ABS(L21)))*ABS(MAX(-L33,0)^1.5-MAX(-L34,0)^1.5)) -> 0 | ... N36: =IF(ABS(N21)<0.000001,IF(N32<0,N9*N12*SQRT(2*(-N32)/N19),0),N9*N10*SQRT(2/N19)*(2/(3*ABS(N21)))*ABS(MAX(-N33,0)^1.5-MAX(-N34,0)^1.5)) -> 0 | P36: AFN-Gleichung | R36: in dieser Rechnung
B37: mpunkt_2 → zone | D37: kg/s | E37: =E19*E35-E20*E36 -> 15.588309 | F37: =F19*F35-F20*F36 -> 12.144673 | G37: =G19*G35-G20*G36 -> 11.529117 | H37: =H19*H35-H20*H36 -> 12.083477 | I37: =I19*I35-I20*I36 -> 11.502084 | J37: =J19*J35-J20*J36 -> 20.220026 | K37: =K19*K35-K20*K36 -> 27.238231 | L37: =L19*L35-L20*L36 -> 26.336952 | ... N37: =N19*N35-N20*N36 -> 25.665916 | P37: P_n (Knoten außen) | R37: 0 (Bezugsdruck)
B38: a_5 | C38: = p_w,2 - p_z | D38: Pa | E38: =E23-E31 -> -3.4434757 | F38: =F23-F31 -> -2.0901171 | G38: =G23-G31 -> -1.8836102 | H38: =H23-H31 -> -2.0691061 | I38: =I23-I31 -> -1.8747875 | J38: =J23-J31 -> -5.7937836 | K38: =K23-K31 -> -10.513726 | L38: =L23-L31 -> -9.8294655 | ... N38: =N23-N31 -> -9.3349591 | P38: P_m (Knoten Zone) | R38: P_z (Unbekannte, Zielwertsuche)
B39: ΔP_unten,5 | C39: z = 0 | D39: Pa | E39: =E38 -> -3.4434757 | F39: =F38 -> -2.0901171 | G39: =G38 -> -1.8836102 | H39: =H38 -> -2.0691061 | I39: =I38 -> -1.8747875 | J39: =J38 -> -5.7937836 | K39: =K38 -> -10.513726 | L39: =L38 -> -9.8294655 | ... N39: =N38 -> -9.3349591 | P39: P_W (Winddruck) | R39: p_w = Cp·½·ρ_außen·U²
B40: ΔP_oben,5 | C40: z = h_tor | D40: Pa | E40: =E38+E21*E11 -> -3.4434757 | F40: =F38+F21*F11 -> -2.0901171 | G40: =G38+G21*G11 -> -1.8836102 | H40: =H38+H21*H11 -> -2.0691061 | I40: =I38+I21*I11 -> -1.8747875 | J40: =J38+J21*J11 -> -5.7937836 | K40: =K38+K21*K11 -> -10.513726 | L40: =L38+L21*L11 -> -9.8294655 | ... N40: =N38+N21*N11 -> -9.3349591 | P40: P_S (Stack) | R40: (ρ_in−ρ_out)·g·z = b·z
B41: Q_ein,5 | D41: m³/s | E41: =IF(ABS(E21)<0.000001,IF(E38>0,E9*E12*SQRT(2*E38/E19),0),E9*E10*SQRT(2/E19)*(2/(3*ABS(E21)))*ABS(MAX(E39,0)^1.5-MAX(E40,0)^1.5)) -> 0 | F41: =IF(ABS(F21)<0.000001,IF(F38>0,F9*F12*SQRT(2*F38/F19),0),F9*F10*SQRT(2/F19)*(2/(3*ABS(F21)))*ABS(MAX(F39,0)^1.5-MAX(F40,0)^1.5)) -> 0 | G41: =IF(ABS(G21)<0.000001,IF(G38>0,G9*G12*SQRT(2*G38/G19),0),G9*G10*SQRT(2/G19)*(2/(3*ABS(G21)))*ABS(MAX(G39,0)^1.5-MAX(G40,0)^1.5)) -> 0 | H41: =IF(ABS(H21)<0.000001,IF(H38>0,H9*H12*SQRT(2*H38/H19),0),H9*H10*SQRT(2/H19)*(2/(3*ABS(H21)))*ABS(MAX(H39,0)^1.5-MAX(H40,0)^1.5)) -> 0 | I41: =IF(ABS(I21)<0.000001,IF(I38>0,I9*I12*SQRT(2*I38/I19),0),I9*I10*SQRT(2/I19)*(2/(3*ABS(I21)))*ABS(MAX(I39,0)^1.5-MAX(I40,0)^1.5)) -> 0 | J41: =IF(ABS(J21)<0.000001,IF(J38>0,J9*J12*SQRT(2*J38/J19),0),J9*J10*SQRT(2/J19)*(2/(3*ABS(J21)))*ABS(MAX(J39,0)^1.5-MAX(J40,0)^1.5)) -> 0 | K41: =IF(ABS(K21)<0.000001,IF(K38>0,K9*K12*SQRT(2*K38/K19),0),K9*K10*SQRT(2/K19)*(2/(3*ABS(K21)))*ABS(MAX(K39,0)^1.5-MAX(K40,0)^1.5)) -> 0 | L41: =IF(ABS(L21)<0.000001,IF(L38>0,L9*L12*SQRT(2*L38/L19),0),L9*L10*SQRT(2/L19)*(2/(3*ABS(L21)))*ABS(MAX(L39,0)^1.5-MAX(L40,0)^1.5)) -> 0 | ... N41: =IF(ABS(N21)<0.000001,IF(N38>0,N9*N12*SQRT(2*N38/N19),0),N9*N10*SQRT(2/N19)*(2/(3*ABS(N21)))*ABS(MAX(N39,0)^1.5-MAX(N40,0)^1.5)) -> 0 | P41: ΔP = P_n−P_m+P_S+P_W | R41: a + b·z
...

Sheet 5.2.3 AFN_2Zonen
E2: AFN_E+ | F2: AFN_CFD_D | G2: AFN_CFD_C1,00 | H2: AFN_E+ | I2: AFN_CFD_D | J2: AFN_CFD_C1,00 | L2: AFN_DIN_1 | M2: AFN_DIN_2
B3: Eingabewerte | E3: 2 | F3: 2 | G3: 2 | H3: 5 | I3: 5 | J3: 5 | L3: 4 | M3: 2 | N3: 4
B4: C_p,2 | C4: Winddruckkoeff. Luv (Tor 2) | D4: - | E4: 0.0325 | F4: ='5.1 C_P'!U6 -> -0.2387075 | G4: ='5.1 C_P'!O6 -> -0.23530067 | H4: 0.48 | I4: ='5.1 C_P'!U9 -> 1.0676863 | J4: ='5.1 C_P'!O9 -> 0.97236047 | L4: 0.5 | M4: -0.8 | N4: 0.7
B5: C_p,5 | C5: Winddruckkoeff. Lee (Tor 5) | D5: - | E5: -0.44 | F5: ='5.1 C_P'!V6 -> -0.52160551 | G5: ='5.1 C_P'!P6 -> -0.51768243 | H5: -0.315 | I5: ='5.1 C_P'!V9 -> -0.3657989 | J5: ='5.1 C_P'!P9 -> -0.36303808 | L5: -0.7 | M5: -0.8 | N5: -0.3
B6: t_außen | D6: °C | E6: 17 | F6: 17 | G6: 17 | H6: 17 | I6: 17 | J6: 17 | L6: 17 | M6: 17 | N6: 17
B7: t_innen | D7: °C | E7: 17 | F7: 17 | G7: 17 | H7: 17 | I7: 17 | J7: 17 | L7: 17 | M7: 17 | N7: 17
B8: b_tor | C8: Breite Tor | D8: m | E8: 3 | F8: 3 | G8: 3 | H8: 3 | I8: 3 | J8: 3 | L8: 3 | M8: 3 | N8: 3
B9: h_tor | C9: Höhe Tor | D9: m | E9: 3 | F9: 3 | G9: 3 | H9: 3 | I9: 3 | J9: 3 | L9: 3 | M9: 3 | N9: 3
B10: A | C10: Öffnungsfläche pro Tor | D10: m² | E10: =E8*E9 -> 9 | F10: =F8*F9 -> 9 | G10: =G8*G9 -> 9 | H10: =H8*H9 -> 9 | I10: =I8*I9 -> 9 | J10: =J8*J9 -> 9 | L10: =L8*L9 -> 9 | M10: =M8*M9 -> 9 | N10: =N8*N9 -> 9
B11: h_spalt | C11: Höhe Spalt | D11: m | E11: 2 | F11: 2 | G11: 2 | H11: 2 | I11: 2 | J11: 2 | L11: 2 | M11: 2 | N11: 2
B12: b_spalt | C12: Breite Spalt | D12: m | E12: 15 | F12: 15 | G12: 15 | H12: 15 | I12: 15 | J12: 15 | L12: 15 | M12: 15 | N12: 15
B13: A_spalt | C13: Öffnungsfläche Spalt | D13: m² | E13: =E11*E12 -> 30 | F13: =F11*F12 -> 30 | G13: =G11*G12 -> 30 | H13: =H11*H12 -> 30 | I13: =I11*I12 -> 30 | J13: =J11*J12 -> 30 | L13: =L11*L12 -> 30 | M13: =M11*M12 -> 30 | N13: =N11*N12 -> 30
B14: A_eff | C14: effektive Fläche | D14: m² | E14: =1/(SQRT(1/E10^2+1/E13^2+1/E10^2)) -> 6.2254302 | F14: =1/(SQRT(1/F10^2+1/F13^2+1/F10^2)) -> 6.2254302 | G14: =1/(SQRT(1/G10^2+1/G13^2+1/G10^2)) -> 6.2254302 | H14: =1/(SQRT(1/H10^2+1/H13^2+1/H10^2)) -> 6.2254302 | I14: =1/(SQRT(1/I10^2+1/I13^2+1/I10^2)) -> 6.2254302 | J14: =1/(SQRT(1/J10^2+1/J13^2+1/J10^2)) -> 6.2254302 | L14: =1/(SQRT(1/L10^2+1/L13^2+1/L10^2)) -> 6.2254302 | M14: =1/(SQRT(1/M10^2+1/M13^2+1/M10^2)) -> 6.2254302 | N14: =1/(SQRT(1/N10^2+1/N13^2+1/N10^2)) -> 6.2254302
B15: C_D | C15: Durchflusskoeffizient | D15: - | E15: 0.62 | F15: 0.62 | G15: 0.62 | H15: 0.62 | I15: 0.62 | J15: 0.62 | L15: 0.62 | M15: 0.62 | N15: 0.62
B16: g | C16: Erdbeschleunigung | D16: m/s² | E16: 9.81 | F16: 9.81 | G16: 9.81 | H16: 9.81 | I16: 9.81 | J16: 9.81 | L16: 9.81 | M16: 9.81 | N16: 9.81
B17: p | C17: Stationsdruck | D17: Pa | E17: 95300 | F17: 95300 | G17: 95300 | H17: 95300 | I17: 95300 | J17: 95300 | L17: 95300 | M17: 95300 | N17: 95300
B18: R | C18: spez. Gaskonstante | D18: J/kgK | E18: 287.06 | F18: 287.06 | G18: 287.06 | H18: 287.06 | I18: 287.06 | J18: 287.06 | L18: 287.06 | M18: 287.06 | N18: 287.06
B19: v_wind (U) | C19: Windgeschwindigkeit auf Torhöhe | D19: m/s | E19: ='4.6.2 Wetter'!$E$9 -> 5.0719645 | F19: ='4.6.2 Wetter'!$E$9 -> 5.0719645 | G19: ='4.6.2 Wetter'!$E$9 -> 5.0719645 | H19: ='4.6.2 Wetter'!$E$9 -> 5.0719645 | I19: ='4.6.2 Wetter'!$E$9 -> 5.0719645 | J19: ='4.6.2 Wetter'!$E$9 -> 5.0719645 | L19: ='4.6.2 Wetter'!$E$9 -> 5.0719645 | M19: ='4.6.2 Wetter'!$E$9 -> 5.0719645 | N19: ='4.6.2 Wetter'!$E$9 -> 5.0719645
B20: T_a, odb | C20: absolute Temperatur außen | D20: K | E20: =E6+273.15 -> 290.15 | F20: =F6+273.15 -> 290.15 | G20: =G6+273.15 -> 290.15 | H20: =H6+273.15 -> 290.15 | I20: =I6+273.15 -> 290.15 | J20: =J6+273.15 -> 290.15 | L20: =L6+273.15 -> 290.15 | M20: =M6+273.15 -> 290.15 | N20: =N6+273.15 -> 290.15
B21: T_i | C21: absolute Temperatur innen | D21: K | E21: =E7+273.15 -> 290.15 | F21: =F7+273.15 -> 290.15 | G21: =G7+273.15 -> 290.15 | H21: =H7+273.15 -> 290.15 | I21: =I7+273.15 -> 290.15 | J21: =J7+273.15 -> 290.15 | L21: =L7+273.15 -> 290.15 | M21: =M7+273.15 -> 290.15 | N21: =N7+273.15 -> 290.15
B22: ρ_a | C22: Luftdichte außen | D22: kg/m³ | E22: 1.13319 | F22: 1.13319 | G22: 1.13319 | H22: 1.13319 | I22: 1.13319 | J22: 1.13319 | L22: 1.13319 | M22: 1.13319 | N22: 1.13319
B23: ρ_i | C23: Luftdichte innen | D23: kg/m³ | E23: 1.13319 | F23: 1.13319 | G23: 1.13319 | H23: 1.13319 | I23: 1.13319 | J23: 1.13319 | L23: 1.13319 | M23: 1.13319 | N23: 1.13319
B24: b | C24: = (ρ_i - ρ_a) * g | D24: Pa/m | E24: =(E23-E22)*E16 -> 0 | F24: =(F23-F22)*F16 -> 0 | G24: =(G23-G22)*G16 -> 0 | H24: =(H23-H22)*H16 -> 0 | I24: =(I23-I22)*I16 -> 0 | J24: =(J23-J22)*J16 -> 0 | L24: =(L23-L22)*L16 -> 0 | M24: =(M23-M22)*M16 -> 0 | N24: =(N23-N22)*N16 -> 0
B25: p_w,2 | C25: Winddruck außen an Tor 2 | D25: Pa | E25: =E4*0.5*E22*E19^2 -> 0.47370559 | F25: =F4*0.5*F22*F19^2 -> -3.4792946 | G25: =G4*0.5*G22*G19^2 -> -3.4296382 | H25: =H4*0.5*H22*H19^2 -> 6.9962672 | I25: =I4*0.5*I22*I19^2 -> 15.562122 | J25: =J4*0.5*J22*J19^2 -> 14.172695 | L25: =L4*0.5*L22*L19^2 -> 7.2877783 | M25: =M4*0.5*M22*M19^2 -> -11.660445 | N25: =N4*0.5*N22*N19^2 -> 10.20289
B26: p_w,5 | C26: Winddruck außen an Tor 5 | D26: Pa | E26: =E5*0.5*E22*E19^2 -> -6.4132449 | F26: =F5*0.5*F22*F19^2 -> -7.6026906 | G26: =G5*0.5*G22*G19^2 -> -7.5455095 | H26: =H5*0.5*H22*H19^2 -> -4.5913003 | I26: =I5*0.5*I22*I19^2 -> -5.3317226 | J26: =J5*0.5*J22*J19^2 -> -5.291482 | L26: =L5*0.5*L22*L19^2 -> -10.20289 | M26: =M5*0.5*M22*M19^2 -> -11.660445 | N26: =N5*0.5*N22*N19^2 -> -4.372667
B27: AFN - Vereinfacht: iso
B28: Q_wind | D28: m³/s | E28: =E15*E14*E19*SQRT(ABS(E4-E5)) -> 13.456688 | F28: =F15*F14*F19*SQRT(ABS(F4-F5)) -> 10.412433 | G28: =G15*G14*G19*SQRT(ABS(G4-G5)) -> 10.402928 | H28: =H15*H14*H19*SQRT(ABS(H4-H5)) -> 17.455039 | I28: =I15*I14*I19*SQRT(ABS(I4-I5)) -> 23.438719 | J28: =J15*J14*J19*SQRT(ABS(J4-J5)) -> 22.62261 | L28: =L15*L14*L19*SQRT(ABS(L4-L5)) -> 21.445091 | M28: =M15*M14*M19*SQRT(ABS(M4-M5)) -> 0 | N28: =N15*N14*N19*SQRT(ABS(N4-N5)) -> 19.5766
B29: Q_ein | D29: m³/s | E29: =E39+E45 -> 13.456768 | F29: =F39+F45 -> 10.413193 | G29: =G39+G45 -> 10.403691 | H29: =H39+H45 -> 17.45508 | I29: =I39+I45 -> 23.439644 | J29: =J39+J45 -> 22.623454
B30: Q_aus | D30: m³/s | E30: =E40+E46 -> 13.456573 | F30: =F40+F46 -> 10.411672 | G30: =G40+G46 -> 10.402164 | H30: =H40+H46 -> 17.454998 | I30: =I40+I46 -> 23.437793 | J30: =J40+J46 -> 22.621765
B31: Q_mittel | D31: m³/s | E31: =(E29+E30)/2 -> 13.456671 | F31: =(F29+F30)/2 -> 10.412433 | G31: =(G29+G30)/2 -> 10.402928 | H31: =(H29+H30)/2 -> 17.455039 | I31: =(I29+I30)/2 -> 23.438719 | J31: =(J29+J30)/2 -> 22.62261
B32: ACH | C32: V = 10 800 m³ | D32: 1/h | E32: =E31*3600/10800 -> 4.4855569 | F32: =F31*3600/10800 -> 3.4708109 | G32: =G31*3600/10800 -> 3.4676425 | H32: =H31*3600/10800 -> 5.8183464 | I32: =I31*3600/10800 -> 7.8129062 | J32: =J31*3600/10800 -> 7.5408699
B33: Zielwertsuche
B34: p_z,A | C34: Druck Zone A | D34: Pa | E34: -2.8215257 | F34: -5.4524996 | G34: -5.3992436 | H34: 1.4519506 | I34: 5.5642781 | J34: 4.8589967
B35: p_z,B | C35: Druck Zone B | D35: Pa | E35: -3.1181093 | F35: -5.6300622 | G35: -5.5764822 | H35: 0.95296436 | I35: 4.6645426 | J35: 4.0208258
B36: a_2 | C36: = p_w,2 - p_z,A | D36: Pa | E36: =E25-E34 -> 3.2952313 | F36: =F25-F34 -> 1.973205 | G36: =G25-G34 -> 1.9696054 | H36: =H25-H34 -> 5.5443166 | I36: =I25-I34 -> 9.9978443 | J36: =J25-J34 -> 9.3136984
B37: ΔP_2,unten,2 | C37: z = 0 | D37: Pa | E37: =E36 -> 3.2952313 | F37: =F36 -> 1.973205 | G37: =G36 -> 1.9696054 | H37: =H36 -> 5.5443166 | I37: =I36 -> 9.9978443 | J37: =J36 -> 9.3136984
B38: ΔP_2,oben,2 | C38: z = h_tor | D38: Pa | E38: =E36+E24*E9 -> 3.2952313 | F38: =F36+F24*F9 -> 1.973205 | G38: =G36+G24*G9 -> 1.9696054 | H38: =H36+H24*H9 -> 5.5443166 | I38: =I36+I24*I9 -> 9.9978443 | J38: =J36+J24*J9 -> 9.3136984
B39: Q_ein,2 | D39: m³/s | E39: =IF(ABS(E24)<0.000001,IF(E36>0,E15*E10*SQRT(2*E36/E22),0),E15*E8*SQRT(2/E22)*(2/(3*ABS(E24)))*ABS(MAX(E37,0)^1.5-MAX(E38,0)^1.5)) -> 13.456768 | F39: =IF(ABS(F24)<0.000001,IF(F36>0,F15*F10*SQRT(2*F36/F22),0),F15*F8*SQRT(2/F22)*(2/(3*ABS(F24)))*ABS(MAX(F37,0)^1.5-MAX(F38,0)^1.5)) -> 10.413193 | G39: =IF(ABS(G24)<0.000001,IF(G36>0,G15*G10*SQRT(2*G36/G22),0),G15*G8*SQRT(2/G22)*(2/(3*ABS(G24)))*ABS(MAX(G37,0)^1.5-MAX(G38,0)^1.5)) -> 10.403691 | H39: =IF(ABS(H24)<0.000001,IF(H36>0,H15*H10*SQRT(2*H36/H22),0),H15*H8*SQRT(2/H22)*(2/(3*ABS(H24)))*ABS(MAX(H37,0)^1.5-MAX(H38,0)^1.5)) -> 17.45508 | I39: =IF(ABS(I24)<0.000001,IF(I36>0,I15*I10*SQRT(2*I36/I22),0),I15*I8*SQRT(2/I22)*(2/(3*ABS(I24)))*ABS(MAX(I37,0)^1.5-MAX(I38,0)^1.5)) -> 23.439644 | J39: =IF(ABS(J24)<0.000001,IF(J36>0,J15*J10*SQRT(2*J36/J22),0),J15*J8*SQRT(2/J22)*(2/(3*ABS(J24)))*ABS(MAX(J37,0)^1.5-MAX(J38,0)^1.5)) -> 22.623454
B40: Q_aus,2 | D40: m³/s | E40: =IF(ABS(E24)<0.000001,IF(E36<0,E15*E10*SQRT(2*(-E36)/E22),0),E15*E8*SQRT(2/E22)*(2/(3*ABS(E24)))*ABS(MAX(-E37,0)^1.5-MAX(-E38,0)^1.5)) -> 0 | F40: =IF(ABS(F24)<0.000001,IF(F36<0,F15*F10*SQRT(2*(-F36)/F22),0),F15*F8*SQRT(2/F22)*(2/(3*ABS(F24)))*ABS(MAX(-F37,0)^1.5-MAX(-F38,0)^1.5)) -> 0 | G40: =IF(ABS(G24)<0.000001,IF(G36<0,G15*G10*SQRT(2*(-G36)/G22),0),G15*G8*SQRT(2/G22)*(2/(3*ABS(G24)))*ABS(MAX(-G37,0)^1.5-MAX(-G38,0)^1.5)) -> 0 | H40: =IF(ABS(H24)<0.000001,IF(H36<0,H15*H10*SQRT(2*(-H36)/H22),0),H15*H8*SQRT(2/H22)*(2/(3*ABS(H24)))*ABS(MAX(-H37,0)^1.5-MAX(-H38,0)^1.5)) -> 0 | I40: =IF(ABS(I24)<0.000001,IF(I36<0,I15*I10*SQRT(2*(-I36)/I22),0),I15*I8*SQRT(2/I22)*(2/(3*ABS(I24)))*ABS(MAX(-I37,0)^1.5-MAX(-I38,0)^1.5)) -> 0 | J40: =IF(ABS(J24)<0.000001,IF(J36<0,J15*J10*SQRT(2*(-J36)/J22),0),J15*J8*SQRT(2/J22)*(2/(3*ABS(J24)))*ABS(MAX(-J37,0)^1.5-MAX(-J38,0)^1.5)) -> 0
B41: mpunkt_2 → zone A | D41: kg/s | E41: =E22*E39-E23*E40 -> 15.249075 | F41: =F22*F39-F23*F40 -> 11.800127 | G41: =G22*G39-G23*G40 -> 11.789359 | H41: =H22*H39-H23*H40 -> 19.779922 | I41: =I22*I39-I23*I40 -> 26.56157 | J41: =J22*J39-J23*J40 -> 25.636672
...

Sheet 5.2.4 C_W-Nachweis
B2: 1. Messung: | D2: C_W = Q_vent/(A * u_Zone), abgelesen aus .csv | G2: Windrichtung 247,5 °
B3: Lauf | C3: Opening Effectiveness | D3: Effective Angle [°] | E3: Δ = |EffAngle - 247,5| [°] | F3: u_Zone [m/s] | G3: Q_vent [m³/s] | H3: C_w
B4: A | C4: autocalculate | D4: 247.5 | E4: 0 | F4: 4.1638 | G4: 20.60759 | H4: =G4/(9*F4) -> 0.54991407
B5: B | C5: autocalculate | D5: 180 | E5: 67.5 | F5: 4.1638 | G5: 6.5543 | H5: =G5/(9*F5) -> 0.17490167
B6: C | C6: autocalculate | D6: 157.5 | E6: 90 | F6: 4.1638 | G6: 1.871208 | H6: =G6/(9*F6) -> 0.049933234
B7: D | C7: autocalculate | D7: 90 | E7: 157.5 | F7: 4.1638 | G7: 0 | H7: =G7/(9*F7) -> 0
B8: E | C8: autocalculate | D8: 0 | E8: 247.5 | F8: 4.1638 | G8: 0 | H8: =G8/(9*F8) -> 0
B9: Kontrolle der Grundgleichung
B10: Test_A1 | C10: fest 1,0 | F10: 4.1638 | G10: 37.47069 | H10: =G10/(9*F10) -> 0.99990634
B11: Test_A2 | C11: fest 1,0 | F11: 5.07 | G11: 45.62625 | H11: =G11/(9*F11) -> 0.99991782 | K11: Interpolationsformel für C_w von EnergyPlus (Quelle: Engineering Reference): Die Engineering Reference formuliert es so: Es ist eine lineare Interpolation zwischen den vom ASHRAE Handbook 2009 (S. 16.13) empfohlenen Werten – 0,5–0,6 für senkrechte und 0,25–0,35 für diagonale Anströmung. EnergyPlus hat daraus 0,55 (senkrecht) und 0,30 (diagonal, = 0,55−0,25) als Endpunkte gewählt und linear dazwischen interpoliert. [Sicher]
E12: linear interpoliert zwischen 0,3 und 0,55 | K12: Gleichung 8.7 im Engineering Reference S. 453
B13: 2. Gegenüberstellung | D13: = 0,55 - (Δ /180)*0,25 | E13: = 0,55 - (Δ/45) * 0,25
B14: Δ [°] | C14: gemessen (Simulation) | D14: Eng Ref Gl. 8.7 | E14: InputOutput S. 642 | F14: ASHRAE 2009 S. 16.13
B15: 0 | C15: =H4 -> 0.54991407 | D15: =0.55-(B15/180)*0.25 -> 0.55 | E15: =MAX(0,0.55-(B15/45)*0.25) -> 0.55 | F15: 0,5 - 0,6
B16: 22.5 | D16: =0.55-(B16/180)*0.25 -> 0.51875 | E16: =MAX(0,0.55-(B16/45)*0.25) -> 0.425
B17: 45 | D17: =0.55-(B17/180)*0.25 -> 0.4875 | E17: =MAX(0,0.55-(B17/45)*0.25) -> 0.3 | F17: 0,25 - 0,35
B18: 67.5 | C18: =H5 -> 0.17490167 | D18: =0.55-(B18/180)*0.25 -> 0.45625 | E18: =MAX(0,0.55-(B18/45)*0.25) -> 0.175
B19: 90 | C19: =H6 -> 0.049933234 | D19: =0.55-(B19/180)*0.25 -> 0.425 | E19: =MAX(0,0.55-(B19/45)*0.25) -> 0.05
B20: 99 | D20: =0.55-(B20/180)*0.25 -> 0.4125 | E20: =MAX(0,0.55-(B20/45)*0.25) -> 0
B21: 112.5 | D21: =0.55-(B21/180)*0.25 -> 0.39375 | E21: =MAX(0,0.55-(B21/45)*0.25) -> 0 | K21: InputOutput S. 642
B22: 157.5 | C22: =H7 -> 0 | D22: =0.55-(B22/180)*0.25 -> 0.33125 | E22: =MAX(0,0.55-(B22/45)*0.25) -> 0
B23: 180 | D23: =0.55-(B23/180)*0.25 -> 0.3 | E23: =MAX(0,0.55-(B23/45)*0.25) -> 0
B24: 247.5 | C24: =H8 -> 0 | D24: =0.55-(B24/180)*0.25 -> 0.20625 | E24: =MAX(0,0.55-(B24/45)*0.25) -> 0
B25: 3. Fehler: Steigung berechnen
B26: Steigung | C26: =(C18-C15)/$B18 -> -0.0055557394 | D26: =(D18-D15)/$B18 -> -0.0013888889 | E26: =(E18-E15)/$B18 -> -0.0055555556 | F26: =(0.3-0.55)/B17 -> -0.0055555556
B27: Bruch | C27: =C26 -> -0.0055557394 | D27: =D26 -> -0.0013888889 | E27: =E26 -> -0.0055555556 | F27: =F26 -> -0.0055555556

Sheet 5.3 CFD
B2: Ergebnisse aus der CFD-Simulation
B3: Variante | C3: Flowdesk | D3: Ausrichtung (Flowdesk) | E3: Windrichtung (ich) | F3: Tore | G3: Barriere | H3: Q_in [m³/s] | I3: Q_out [m³/s] | J3: Q_mean [m³/s] | K3: mass imbalance | L3: ACH [1/h]
B5: 1 | C5: 1 | D5: 0° | E5: 247,5° | F5: 2 + 5 | G5: nein | H5: 9.6 | I5: 10.014 | J5: =AVERAGE(H5:I5) -> 9.807 | K5: =ABS(H5-I5)/MAX(ABS(H5),ABS(I5)) -> 0.041342121 | L5: =J5*3600/10800 -> 3.269
